Workbook
Name a_coupon: Inputs!$B$15
Name a_notional: Inputs!$B$14
Name b_coupon: Inputs!$B$17
Name b_notional: Inputs!$B$16
Name case_number: Case!$B$2
Name coupon: Inputs!$B$10
Name face: Inputs!$B$9
Name lgd: Inputs!$B$12
Name Number_of_Cases: Inputs!$B$21
Name pd_annual: Inputs!$B$11
Name rho: Inputs!$B$13

Sheet Inputs
A1: Miniproject 3 (Part 1) - Simplified CDO analysis
A2: FRE 6103 Valuation for Financial Engineering (NYU Tandon) | Raj Pawar (rsp9234) and Michael Brick (mb11311)
A3: Yellow cells are inputs; everything else in the workbook is a formula. All amounts are in $ millions. The case to display is chosen on the Case sheet.
A5: Parameter | B5: Value | C5: Note
A6: Number of bonds | B6: 10 | C6: Fixed by the layout of the sheets (10 columns per block).
A7: Years to maturity | B7: 5 | C7: Fixed by the layout (20 quarterly columns).
A8: Payments per year | B8: 4 | C8: Quarterly.
A9: Face value per bond ($MM) | B9: 10 | C9: Given.
A10: Coupon rate, annual | B10: 0.06 | C10: Given. Paid quarterly: coupon / 4 x face.
A11: Default probability, annual (pi) | B11: 0.04 | C11: Given. Default time in years t = ln(1 - u) / ln(1 - pi).
A12: Loss given default (lambda) | B12: 0.6 | C12: Given. BIS model: 1 - LGD of every promised payment is always paid.
A13: Correlation between default dates | B13: 0.2 | C13: Given. Applied to the normals through the Cholesky factor.
A14: Class A notional ($MM) | B14: 20 | C14: Given.
A15: Class A coupon, annual | B15: 0.02 | C15: Given. Paid quarterly, principal at maturity.
A16: Class B notional ($MM) | B16: 10 | C16: Given.
A17: Class B coupon, annual | B17: 0.04 | C17: Given. Paid quarterly, principal at maturity.
... A19: Risk-free rate | B19: 0.01 | C19: Given. Not used until Part 2.
A20: Seed of the fixed random numbers | B20: 6103
A21: Number of cases | B21: =COUNT(Random!$A$18:$A$1017) -> 1000 | C21: Given. Counted from the Random sheet: the layout has one row per case, so this is not an input.
A23: Promised cash flows ($MM)
A24: Quarter | B24: One bond | C24: Pool (10 bonds) | D24: Due to Class A | E24: Due to Class B
A25: 1 | B25: =face*coupon/4+IF(A25=20,face,0) -> 0.15 | C25: =10*B25 -> 1.5 | D25: =a_notional*a_coupon/4+IF(A25=20,a_notional,0) -> 0.1 | E25: =b_notional*b_coupon/4+IF(A25=20,b_notional,0) -> 0.1
A26: 2 | B26: =face*coupon/4+IF(A26=20,face,0) -> 0.15 | C26: =10*B26 -> 1.5 | D26: =a_notional*a_coupon/4+IF(A26=20,a_notional,0) -> 0.1 | E26: =b_notional*b_coupon/4+IF(A26=20,b_notional,0) -> 0.1
A27: 3 | B27: =face*coupon/4+IF(A27=20,face,0) -> 0.15 | C27: =10*B27 -> 1.5 | D27: =a_notional*a_coupon/4+IF(A27=20,a_notional,0) -> 0.1 | E27: =b_notional*b_coupon/4+IF(A27=20,b_notional,0) -> 0.1
A28: 4 | B28: =face*coupon/4+IF(A28=20,face,0) -> 0.15 | C28: =10*B28 -> 1.5 | D28: =a_notional*a_coupon/4+IF(A28=20,a_notional,0) -> 0.1 | E28: =b_notional*b_coupon/4+IF(A28=20,b_notional,0) -> 0.1
A29: 5 | B29: =face*coupon/4+IF(A29=20,face,0) -> 0.15 | C29: =10*B29 -> 1.5 | D29: =a_notional*a_coupon/4+IF(A29=20,a_notional,0) -> 0.1 | E29: =b_notional*b_coupon/4+IF(A29=20,b_notional,0) -> 0.1
A30: 6 | B30: =face*coupon/4+IF(A30=20,face,0) -> 0.15 | C30: =10*B30 -> 1.5 | D30: =a_notional*a_coupon/4+IF(A30=20,a_notional,0) -> 0.1 | E30: =b_notional*b_coupon/4+IF(A30=20,b_notional,0) -> 0.1
A31: 7 | B31: =face*coupon/4+IF(A31=20,face,0) -> 0.15 | C31: =10*B31 -> 1.5 | D31: =a_notional*a_coupon/4+IF(A31=20,a_notional,0) -> 0.1 | E31: =b_notional*b_coupon/4+IF(A31=20,b_notional,0) -> 0.1
A32: 8 | B32: =face*coupon/4+IF(A32=20,face,0) -> 0.15 | C32: =10*B32 -> 1.5 | D32: =a_notional*a_coupon/4+IF(A32=20,a_notional,0) -> 0.1 | E32: =b_notional*b_coupon/4+IF(A32=20,b_notional,0) -> 0.1
A33: 9 | B33: =face*coupon/4+IF(A33=20,face,0) -> 0.15 | C33: =10*B33 -> 1.5 | D33: =a_notional*a_coupon/4+IF(A33=20,a_notional,0) -> 0.1 | E33: =b_notional*b_coupon/4+IF(A33=20,b_notional,0) -> 0.1
A34: 10 | B34: =face*coupon/4+IF(A34=20,face,0) -> 0.15 | C34: =10*B34 -> 1.5 | D34: =a_notional*a_coupon/4+IF(A34=20,a_notional,0) -> 0.1 | E34: =b_notional*b_coupon/4+IF(A34=20,b_notional,0) -> 0.1
A35: 11 | B35: =face*coupon/4+IF(A35=20,face,0) -> 0.15 | C35: =10*B35 -> 1.5 | D35: =a_notional*a_coupon/4+IF(A35=20,a_notional,0) -> 0.1 | E35: =b_notional*b_coupon/4+IF(A35=20,b_notional,0) -> 0.1
A36: 12 | B36: =face*coupon/4+IF(A36=20,face,0) -> 0.15 | C36: =10*B36 -> 1.5 | D36: =a_notional*a_coupon/4+IF(A36=20,a_notional,0) -> 0.1 | E36: =b_notional*b_coupon/4+IF(A36=20,b_notional,0) -> 0.1
... A44: 20 | B44: =face*coupon/4+IF(A44=20,face,0) -> 10.15 | C44: =10*B44 -> 101.5 | D44: =a_notional*a_coupon/4+IF(A44=20,a_notional,0) -> 20.1 | E44: =b_notional*b_coupon/4+IF(A44=20,b_notional,0) -> 10.1
A45: Total | B45: =SUM(B25:B44) -> 13 | C45: =SUM(C25:C44) -> 130 | D45: =SUM(D25:D44) -> 22 | E45: =SUM(E25:E44) -> 12

Sheet Case
A1: Case viewer
A2: Case to display (1 to 1000) | B2: 5 | C2: Type any case number in the yellow cell. Everything on this sheet follows it.
A5: Bond | B5: Random normal z | C5: Moment-matched z | D5: Correlated normal x | E5: Uniform u | F5: Default time (years) | G5: Default quarter (21 = none) | H5: Status | I5: Total cash received ($MM)
A6: Bond 1 | B6: =INDEX(Random!$B$18:$K$1017,case_number,1) -> -1.8599871 | C6: =INDEX(Random!$X$18:$AG$1017,case_number,1) -> -1.8690173 | D6: =INDEX(Defaults!$B$18:$K$1017,case_number,1) -> -1.8690173 | E6: =INDEX(Defaults!$M$18:$V$1017,case_number,1) -> 0.030810203 | F6: =INDEX(Defaults!$X$18:$AG$1017,case_number,1) -> 0.76661658 | G6: =INDEX(Defaults!$AI$18:$AR$1017,case_number,1) -> 4 | H6: =IF(G6<=20,"defaults in quarter "&G6,"survives") -> defaults in quarter 4 | I6: =SUM(B20:B39) -> 5.47
A7: Bond 2 | B7: =INDEX(Random!$B$18:$K$1017,case_number,2) -> 0.75061757 | C7: =INDEX(Random!$X$18:$AG$1017,case_number,2) -> 0.73225356 | D7: =INDEX(Defaults!$B$18:$K$1017,case_number,2) -> 0.34365558 | E7: =INDEX(Defaults!$M$18:$V$1017,case_number,2) -> 0.63444734 | F7: =INDEX(Defaults!$X$18:$AG$1017,case_number,2) -> 24.652027 | G7: =INDEX(Defaults!$AI$18:$AR$1017,case_number,2) -> 21 | H7: =IF(G7<=20,"defaults in quarter "&G7,"survives") -> survives | I7: =SUM(C20:C39) -> 13
A8: Bond 3 | B8: =INDEX(Random!$B$18:$K$1017,case_number,3) -> 0.2224588 | C8: =INDEX(Random!$X$18:$AG$1017,case_number,3) -> 0.18387329 | D8: =INDEX(Defaults!$B$18:$K$1017,case_number,3) -> -0.076588476 | E8: =INDEX(Defaults!$M$18:$V$1017,case_number,3) -> 0.46947546 | F8: =INDEX(Defaults!$X$18:$AG$1017,case_number,3) -> 15.528126 | G8: =INDEX(Defaults!$AI$18:$AR$1017,case_number,3) -> 21 | H8: =IF(G8<=20,"defaults in quarter "&G8,"survives") -> survives | I8: =SUM(D20:D39) -> 13
A9: Bond 4 | B9: =INDEX(Random!$B$18:$K$1017,case_number,4) -> -0.78341897 | C9: =INDEX(Random!$X$18:$AG$1017,case_number,4) -> -0.72151866 | D9: =INDEX(Defaults!$B$18:$K$1017,case_number,4) -> -0.91875382 | E9: =INDEX(Defaults!$M$18:$V$1017,case_number,4) -> 0.17911217 | F9: =INDEX(Defaults!$X$18:$AG$1017,case_number,4) -> 4.8348645 | G9: =INDEX(Defaults!$AI$18:$AR$1017,case_number,4) -> 20 | H9: =IF(G9<=20,"defaults in quarter "&G9,"survives") -> defaults in quarter 20 | I9: =SUM(E20:E39) -> 6.91
A10: Bond 5 | B10: =INDEX(Random!$B$18:$K$1017,case_number,5) -> -1.5263177 | C10: =INDEX(Random!$X$18:$AG$1017,case_number,5) -> -1.4417872 | D10: =INDEX(Defaults!$B$18:$K$1017,case_number,5) -> -1.6828875 | E10: =INDEX(Defaults!$M$18:$V$1017,case_number,5) -> 0.046198439 | F10: =INDEX(Defaults!$X$18:$AG$1017,case_number,5) -> 1.1586802 | G10: =INDEX(Defaults!$AI$18:$AR$1017,case_number,5) -> 5 | H10: =IF(G10<=20,"defaults in quarter "&G10,"survives") -> defaults in quarter 5 | I10: =SUM(F20:F39) -> 5.56
A11: Bond 6 | B11: =INDEX(Random!$B$18:$K$1017,case_number,6) -> -0.78531154 | C11: =INDEX(Random!$X$18:$AG$1017,case_number,6) -> -0.74971084 | D11: =INDEX(Defaults!$B$18:$K$1017,case_number,6) -> -1.1738999 | E11: =INDEX(Defaults!$M$18:$V$1017,case_number,6) -> 0.12021756 | F11: =INDEX(Defaults!$X$18:$AG$1017,case_number,6) -> 3.1375398 | G11: =INDEX(Defaults!$AI$18:$AR$1017,case_number,6) -> 13 | H11: =IF(G11<=20,"defaults in quarter "&G11,"survives") -> defaults in quarter 13 | I11: =SUM(G20:G39) -> 6.28
A12: Bond 7 | B12: =INDEX(Random!$B$18:$K$1017,case_number,7) -> -0.83463465 | C12: =INDEX(Random!$X$18:$AG$1017,case_number,7) -> -0.73423477 | D12: =INDEX(Defaults!$B$18:$K$1017,case_number,7) -> -1.2265224 | E12: =INDEX(Defaults!$M$18:$V$1017,case_number,7) -> 0.11000107 | F12: =INDEX(Defaults!$X$18:$AG$1017,case_number,7) -> 2.8547117 | G12: =INDEX(Defaults!$AI$18:$AR$1017,case_number,7) -> 12 | H12: =IF(G12<=20,"defaults in quarter "&G12,"survives") -> defaults in quarter 12 | I12: =SUM(H20:H39) -> 6.19
A13: Bond 8 | B13: =INDEX(Random!$B$18:$K$1017,case_number,8) -> -0.079703706 | C13: =INDEX(Random!$X$18:$AG$1017,case_number,8) -> -0.10079161 | D13: =INDEX(Defaults!$B$18:$K$1017,case_number,8) -> -0.69452428 | E13: =INDEX(Defaults!$M$18:$V$1017,case_number,8) -> 0.24367674 | F13: =INDEX(Defaults!$X$18:$AG$1017,case_number,8) -> 6.8415667 | G13: =INDEX(Defaults!$AI$18:$AR$1017,case_number,8) -> 21 | H13: =IF(G13<=20,"defaults in quarter "&G13,"survives") -> survives | I13: =SUM(I20:I39) -> 13
A14: Bond 9 | B14: =INDEX(Random!$B$18:$K$1017,case_number,9) -> -0.83237702 | C14: =INDEX(Random!$X$18:$AG$1017,case_number,9) -> -0.95491939 | D14: =INDEX(Defaults!$B$18:$K$1017,case_number,9) -> -1.4971931 | E14: =INDEX(Defaults!$M$18:$V$1017,case_number,9) -> 0.067171513 | F14: =INDEX(Defaults!$X$18:$AG$1017,case_number,9) -> 1.7033446 | G14: =INDEX(Defaults!$AI$18:$AR$1017,case_number,9) -> 7 | H14: =IF(G14<=20,"defaults in quarter "&G14,"survives") -> defaults in quarter 7 | I14: =SUM(J20:J39) -> 5.74
A15: Bond 10 | B15: =INDEX(Random!$B$18:$K$1017,case_number,10) -> 0.28584576 | C15: =INDEX(Random!$X$18:$AG$1017,case_number,10) -> 0.25074514 | D15: =INDEX(Defaults!$B$18:$K$1017,case_number,10) -> -0.44385533 | E15: =INDEX(Defaults!$M$18:$V$1017,case_number,10) -> 0.32857359 | F15: =INDEX(Defaults!$X$18:$AG$1017,case_number,10) -> 9.758241 | G15: =INDEX(Defaults!$AI$18:$AR$1017,case_number,10) -> 21 | H15: =IF(G15<=20,"defaults in quarter "&G15,"survives") -> survives | I15: =SUM(K20:K39) -> 13
A16: Bonds defaulting within 5 years | G16: =COUNTIF(G6:G15,"<=20") -> 6
A19: Quarter | B19: Bond 1 | C19: Bond 2 | D19: Bond 3 | E19: Bond 4 | F19: Bond 5 | G19: Bond 6 | H19: Bond 7 | I19: Bond 8 | J19: Bond 9 | K19: Bond 10 | L19: Pool | M19: Class A | N19: Class B | O19: Equity | P19: Pool promised
A20: 1 | B20: =Inputs!$B$25*IF($A20>=$G$6,1-lgd,1) -> 0.15 | C20: =Inputs!$B$25*IF($A20>=$G$7,1-lgd,1) -> 0.15 | D20: =Inputs!$B$25*IF($A20>=$G$8,1-lgd,1) -> 0.15 | E20: =Inputs!$B$25*IF($A20>=$G$9,1-lgd,1) -> 0.15 | F20: =Inputs!$B$25*IF($A20>=$G$10,1-lgd,1) -> 0.15 | G20: =Inputs!$B$25*IF($A20>=$G$11,1-lgd,1) -> 0.15 | H20: =Inputs!$B$25*IF($A20>=$G$12,1-lgd,1) -> 0.15 | I20: =Inputs!$B$25*IF($A20>=$G$13,1-lgd,1) -> 0.15 | J20: =Inputs!$B$25*IF($A20>=$G$14,1-lgd,1) -> 0.15 | K20: =Inputs!$B$25*IF($A20>=$G$15,1-lgd,1) -> 0.15 | L20: =SUM(B20:K20) -> 1.5 | M20: =MIN(L20,Inputs!$D$25) -> 0.1 | N20: =MIN(L20-M20,Inputs!$E$25) -> 0.1 | O20: =L20-M20-N20 -> 1.3 | P20: =Inputs!$C$25 -> 1.5
A21: 2 | B21: =Inputs!$B$26*IF($A21>=$G$6,1-lgd,1) -> 0.15 | C21: =Inputs!$B$26*IF($A21>=$G$7,1-lgd,1) -> 0.15 | D21: =Inputs!$B$26*IF($A21>=$G$8,1-lgd,1) -> 0.15 | E21: =Inputs!$B$26*IF($A21>=$G$9,1-lgd,1) -> 0.15 | F21: =Inputs!$B$26*IF($A21>=$G$10,1-lgd,1) -> 0.15 | G21: =Inputs!$B$26*IF($A21>=$G$11,1-lgd,1) -> 0.15 | H21: =Inputs!$B$26*IF($A21>=$G$12,1-lgd,1) -> 0.15 | I21: =Inputs!$B$26*IF($A21>=$G$13,1-lgd,1) -> 0.15 | J21: =Inputs!$B$26*IF($A21>=$G$14,1-lgd,1) -> 0.15 | K21: =Inputs!$B$26*IF($A21>=$G$15,1-lgd,1) -> 0.15 | L21: =SUM(B21:K21) -> 1.5 | M21: =MIN(L21,Inputs!$D$26) -> 0.1 | N21: =MIN(L21-M21,Inputs!$E$26) -> 0.1 | O21: =L21-M21-N21 -> 1.3 | P21: =Inputs!$C$26 -> 1.5
A22: 3 | B22: =Inputs!$B$27*IF($A22>=$G$6,1-lgd,1) -> 0.15 | C22: =Inputs!$B$27*IF($A22>=$G$7,1-lgd,1) -> 0.15 | D22: =Inputs!$B$27*IF($A22>=$G$8,1-lgd,1) -> 0.15 | E22: =Inputs!$B$27*IF($A22>=$G$9,1-lgd,1) -> 0.15 | F22: =Inputs!$B$27*IF($A22>=$G$10,1-lgd,1) -> 0.15 | G22: =Inputs!$B$27*IF($A22>=$G$11,1-lgd,1) -> 0.15 | H22: =Inputs!$B$27*IF($A22>=$G$12,1-lgd,1) -> 0.15 | I22: =Inputs!$B$27*IF($A22>=$G$13,1-lgd,1) -> 0.15 | J22: =Inputs!$B$27*IF($A22>=$G$14,1-lgd,1) -> 0.15 | K22: =Inputs!$B$27*IF($A22>=$G$15,1-lgd,1) -> 0.15 | L22: =SUM(B22:K22) -> 1.5 | M22: =MIN(L22,Inputs!$D$27) -> 0.1 | N22: =MIN(L22-M22,Inputs!$E$27) -> 0.1 | O22: =L22-M22-N22 -> 1.3 | P22: =Inputs!$C$27 -> 1.5
A23: 4 | B23: =Inputs!$B$28*IF($A23>=$G$6,1-lgd,1) -> 0.06 | C23: =Inputs!$B$28*IF($A23>=$G$7,1-lgd,1) -> 0.15 | D23: =Inputs!$B$28*IF($A23>=$G$8,1-lgd,1) -> 0.15 | E23: =Inputs!$B$28*IF($A23>=$G$9,1-lgd,1) -> 0.15 | F23: =Inputs!$B$28*IF($A23>=$G$10,1-lgd,1) -> 0.15 | G23: =Inputs!$B$28*IF($A23>=$G$11,1-lgd,1) -> 0.15 | H23: =Inputs!$B$28*IF($A23>=$G$12,1-lgd,1) -> 0.15 | I23: =Inputs!$B$28*IF($A23>=$G$13,1-lgd,1) -> 0.15 | J23: =Inputs!$B$28*IF($A23>=$G$14,1-lgd,1) -> 0.15 | K23: =Inputs!$B$28*IF($A23>=$G$15,1-lgd,1) -> 0.15 | L23: =SUM(B23:K23) -> 1.41 | M23: =MIN(L23,Inputs!$D$28) -> 0.1 | N23: =MIN(L23-M23,Inputs!$E$28) -> 0.1 | O23: =L23-M23-N23 -> 1.21 | P23: =Inputs!$C$28 -> 1.5
A24: 5 | B24: =Inputs!$B$29*IF($A24>=$G$6,1-lgd,1) -> 0.06 | C24: =Inputs!$B$29*IF($A24>=$G$7,1-lgd,1) -> 0.15 | D24: =Inputs!$B$29*IF($A24>=$G$8,1-lgd,1) -> 0.15 | E24: =Inputs!$B$29*IF($A24>=$G$9,1-lgd,1) -> 0.15 | F24: =Inputs!$B$29*IF($A24>=$G$10,1-lgd,1) -> 0.06 | G24: =Inputs!$B$29*IF($A24>=$G$11,1-lgd,1) -> 0.15 | H24: =Inputs!$B$29*IF($A24>=$G$12,1-lgd,1) -> 0.15 | I24: =Inputs!$B$29*IF($A24>=$G$13,1-lgd,1) -> 0.15 | J24: =Inputs!$B$29*IF($A24>=$G$14,1-lgd,1) -> 0.15 | K24: =Inputs!$B$29*IF($A24>=$G$15,1-lgd,1) -> 0.15 | L24: =SUM(B24:K24) -> 1.32 | M24: =MIN(L24,Inputs!$D$29) -> 0.1 | N24: =MIN(L24-M24,Inputs!$E$29) -> 0.1 | O24: =L24-M24-N24 -> 1.12 | P24: =Inputs!$C$29 -> 1.5
A25: 6 | B25: =Inputs!$B$30*IF($A25>=$G$6,1-lgd,1) -> 0.06 | C25: =Inputs!$B$30*IF($A25>=$G$7,1-lgd,1) -> 0.15 | D25: =Inputs!$B$30*IF($A25>=$G$8,1-lgd,1) -> 0.15 | E25: =Inputs!$B$30*IF($A25>=$G$9,1-lgd,1) -> 0.15 | F25: =Inputs!$B$30*IF($A25>=$G$10,1-lgd,1) -> 0.06 | G25: =Inputs!$B$30*IF($A25>=$G$11,1-lgd,1) -> 0.15 | H25: =Inputs!$B$30*IF($A25>=$G$12,1-lgd,1) -> 0.15 | I25: =Inputs!$B$30*IF($A25>=$G$13,1-lgd,1) -> 0.15 | J25: =Inputs!$B$30*IF($A25>=$G$14,1-lgd,1) -> 0.15 | K25: =Inputs!$B$30*IF($A25>=$G$15,1-lgd,1) -> 0.15 | L25: =SUM(B25:K25) -> 1.32 | M25: =MIN(L25,Inputs!$D$30) -> 0.1 | N25: =MIN(L25-M25,Inputs!$E$30) -> 0.1 | O25: =L25-M25-N25 -> 1.12 | P25: =Inputs!$C$30 -> 1.5
A26: 7 | B26: =Inputs!$B$31*IF($A26>=$G$6,1-lgd,1) -> 0.06 | C26: =Inputs!$B$31*IF($A26>=$G$7,1-lgd,1) -> 0.15 | D26: =Inputs!$B$31*IF($A26>=$G$8,1-lgd,1) -> 0.15 | E26: =Inputs!$B$31*IF($A26>=$G$9,1-lgd,1) -> 0.15 | F26: =Inputs!$B$31*IF($A26>=$G$10,1-lgd,1) -> 0.06 | G26: =Inputs!$B$31*IF($A26>=$G$11,1-lgd,1) -> 0.15 | H26: =Inputs!$B$31*IF($A26>=$G$12,1-lgd,1) -> 0.15 | I26: =Inputs!$B$31*IF($A26>=$G$13,1-lgd,1) -> 0.15 | J26: =Inputs!$B$31*IF($A26>=$G$14,1-lgd,1) -> 0.06 | K26: =Inputs!$B$31*IF($A26>=$G$15,1-lgd,1) -> 0.15 | L26: =SUM(B26:K26) -> 1.23 | M26: =MIN(L26,Inputs!$D$31) -> 0.1 | N26: =MIN(L26-M26,Inputs!$E$31) -> 0.1 | O26: =L26-M26-N26 -> 1.03 | P26: =Inputs!$C$31 -> 1.5
A27: 8 | B27: =Inputs!$B$32*IF($A27>=$G$6,1-lgd,1) -> 0.06 | C27: =Inputs!$B$32*IF($A27>=$G$7,1-lgd,1) -> 0.15 | D27: =Inputs!$B$32*IF($A27>=$G$8,1-lgd,1) -> 0.15 | E27: =Inputs!$B$32*IF($A27>=$G$9,1-lgd,1) -> 0.15 | F27: =Inputs!$B$32*IF($A27>=$G$10,1-lgd,1) -> 0.06 | G27: =Inputs!$B$32*IF($A27>=$G$11,1-lgd,1) -> 0.15 | H27: =Inputs!$B$32*IF($A27>=$G$12,1-lgd,1) -> 0.15 | I27: =Inputs!$B$32*IF($A27>=$G$13,1-lgd,1) -> 0.15 | J27: =Inputs!$B$32*IF($A27>=$G$14,1-lgd,1) -> 0.06 | K27: =Inputs!$B$32*IF($A27>=$G$15,1-lgd,1) -> 0.15 | L27: =SUM(B27:K27) -> 1.23 | M27: =MIN(L27,Inputs!$D$32) -> 0.1 | N27: =MIN(L27-M27,Inputs!$E$32) -> 0.1 | O27: =L27-M27-N27 -> 1.03 | P27: =Inputs!$C$32 -> 1.5
A28: 9 | B28: =Inputs!$B$33*IF($A28>=$G$6,1-lgd,1) -> 0.06 | C28: =Inputs!$B$33*IF($A28>=$G$7,1-lgd,1) -> 0.15 | D28: =Inputs!$B$33*IF($A28>=$G$8,1-lgd,1) -> 0.15 | E28: =Inputs!$B$33*IF($A28>=$G$9,1-lgd,1) -> 0.15 | F28: =Inputs!$B$33*IF($A28>=$G$10,1-lgd,1) -> 0.06 | G28: =Inputs!$B$33*IF($A28>=$G$11,1-lgd,1) -> 0.15 | H28: =Inputs!$B$33*IF($A28>=$G$12,1-lgd,1) -> 0.15 | I28: =Inputs!$B$33*IF($A28>=$G$13,1-lgd,1) -> 0.15 | J28: =Inputs!$B$33*IF($A28>=$G$14,1-lgd,1) -> 0.06 | K28: =Inputs!$B$33*IF($A28>=$G$15,1-lgd,1) -> 0.15 | L28: =SUM(B28:K28) -> 1.23 | M28: =MIN(L28,Inputs!$D$33) -> 0.1 | N28: =MIN(L28-M28,Inputs!$E$33) -> 0.1 | O28: =L28-M28-N28 -> 1.03 | P28: =Inputs!$C$33 -> 1.5
A29: 10 | B29: =Inputs!$B$34*IF($A29>=$G$6,1-lgd,1) -> 0.06 | C29: =Inputs!$B$34*IF($A29>=$G$7,1-lgd,1) -> 0.15 | D29: =Inputs!$B$34*IF($A29>=$G$8,1-lgd,1) -> 0.15 | E29: =Inputs!$B$34*IF($A29>=$G$9,1-lgd,1) -> 0.15 | F29: =Inputs!$B$34*IF($A29>=$G$10,1-lgd,1) -> 0.06 | G29: =Inputs!$B$34*IF($A29>=$G$11,1-lgd,1) -> 0.15 | H29: =Inputs!$B$34*IF($A29>=$G$12,1-lgd,1) -> 0.15 | I29: =Inputs!$B$34*IF($A29>=$G$13,1-lgd,1) -> 0.15 | J29: =Inputs!$B$34*IF($A29>=$G$14,1-lgd,1) -> 0.06 | K29: =Inputs!$B$34*IF($A29>=$G$15,1-lgd,1) -> 0.15 | L29: =SUM(B29:K29) -> 1.23 | M29: =MIN(L29,Inputs!$D$34) -> 0.1 | N29: =MIN(L29-M29,Inputs!$E$34) -> 0.1 | O29: =L29-M29-N29 -> 1.03 | P29: =Inputs!$C$34 -> 1.5
A30: 11 | B30: =Inputs!$B$35*IF($A30>=$G$6,1-lgd,1) -> 0.06 | C30: =Inputs!$B$35*IF($A30>=$G$7,1-lgd,1) -> 0.15 | D30: =Inputs!$B$35*IF($A30>=$G$8,1-lgd,1) -> 0.15 | E30: =Inputs!$B$35*IF($A30>=$G$9,1-lgd,1) -> 0.15 | F30: =Inputs!$B$35*IF($A30>=$G$10,1-lgd,1) -> 0.06 | G30: =Inputs!$B$35*IF($A30>=$G$11,1-lgd,1) -> 0.15 | H30: =Inputs!$B$35*IF($A30>=$G$12,1-lgd,1) -> 0.15 | I30: =Inputs!$B$35*IF($A30>=$G$13,1-lgd,1) -> 0.15 | J30: =Inputs!$B$35*IF($A30>=$G$14,1-lgd,1) -> 0.06 | K30: =Inputs!$B$35*IF($A30>=$G$15,1-lgd,1) -> 0.15 | L30: =SUM(B30:K30) -> 1.23 | M30: =MIN(L30,Inputs!$D$35) -> 0.1 | N30: =MIN(L30-M30,Inputs!$E$35) -> 0.1 | O30: =L30-M30-N30 -> 1.03 | P30: =Inputs!$C$35 -> 1.5
A31: 12 | B31: =Inputs!$B$36*IF($A31>=$G$6,1-lgd,1) -> 0.06 | C31: =Inputs!$B$36*IF($A31>=$G$7,1-lgd,1) -> 0.15 | D31: =Inputs!$B$36*IF($A31>=$G$8,1-lgd,1) -> 0.15 | E31: =Inputs!$B$36*IF($A31>=$G$9,1-lgd,1) -> 0.15 | F31: =Inputs!$B$36*IF($A31>=$G$10,1-lgd,1) -> 0.06 | G31: =Inputs!$B$36*IF($A31>=$G$11,1-lgd,1) -> 0.15 | H31: =Inputs!$B$36*IF($A31>=$G$12,1-lgd,1) -> 0.06 | I31: =Inputs!$B$36*IF($A31>=$G$13,1-lgd,1) -> 0.15 | J31: =Inputs!$B$36*IF($A31>=$G$14,1-lgd,1) -> 0.06 | K31: =Inputs!$B$36*IF($A31>=$G$15,1-lgd,1) -> 0.15 | L31: =SUM(B31:K31) -> 1.14 | M31: =MIN(L31,Inputs!$D$36) -> 0.1 | N31: =MIN(L31-M31,Inputs!$E$36) -> 0.1 | O31: =L31-M31-N31 -> 0.94 | P31: =Inputs!$C$36 -> 1.5
A32: 13 | B32: =Inputs!$B$37*IF($A32>=$G$6,1-lgd,1) -> 0.06 | C32: =Inputs!$B$37*IF($A32>=$G$7,1-lgd,1) -> 0.15 | D32: =Inputs!$B$37*IF($A32>=$G$8,1-lgd,1) -> 0.15 | E32: =Inputs!$B$37*IF($A32>=$G$9,1-lgd,1) -> 0.15 | F32: =Inputs!$B$37*IF($A32>=$G$10,1-lgd,1) -> 0.06 | G32: =Inputs!$B$37*IF($A32>=$G$11,1-lgd,1) -> 0.06 | H32: =Inputs!$B$37*IF($A32>=$G$12,1-lgd,1) -> 0.06 | I32: =Inputs!$B$37*IF($A32>=$G$13,1-lgd,1) -> 0.15 | J32: =Inputs!$B$37*IF($A32>=$G$14,1-lgd,1) -> 0.06 | K32: =Inputs!$B$37*IF($A32>=$G$15,1-lgd,1) -> 0.15 | L32: =SUM(B32:K32) -> 1.05 | M32: =MIN(L32,Inputs!$D$37) -> 0.1 | N32: =MIN(L32-M32,Inputs!$E$37) -> 0.1 | O32: =L32-M32-N32 -> 0.85 | P32: =Inputs!$C$37 -> 1.5
A33: 14 | B33: =Inputs!$B$38*IF($A33>=$G$6,1-lgd,1) -> 0.06 | C33: =Inputs!$B$38*IF($A33>=$G$7,1-lgd,1) -> 0.15 | D33: =Inputs!$B$38*IF($A33>=$G$8,1-lgd,1) -> 0.15 | E33: =Inputs!$B$38*IF($A33>=$G$9,1-lgd,1) -> 0.15 | F33: =Inputs!$B$38*IF($A33>=$G$10,1-lgd,1) -> 0.06 | G33: =Inputs!$B$38*IF($A33>=$G$11,1-lgd,1) -> 0.06 | H33: =Inputs!$B$38*IF($A33>=$G$12,1-lgd,1) -> 0.06 | I33: =Inputs!$B$38*IF($A33>=$G$13,1-lgd,1) -> 0.15 | J33: =Inputs!$B$38*IF($A33>=$G$14,1-lgd,1) -> 0.06 | K33: =Inputs!$B$38*IF($A33>=$G$15,1-lgd,1) -> 0.15 | L33: =SUM(B33:K33) -> 1.05 | M33: =MIN(L33,Inputs!$D$38) -> 0.1 | N33: =MIN(L33-M33,Inputs!$E$38) -> 0.1 | O33: =L33-M33-N33 -> 0.85 | P33: =Inputs!$C$38 -> 1.5
A34: 15 | B34: =Inputs!$B$39*IF($A34>=$G$6,1-lgd,1) -> 0.06 | C34: =Inputs!$B$39*IF($A34>=$G$7,1-lgd,1) -> 0.15 | D34: =Inputs!$B$39*IF($A34>=$G$8,1-lgd,1) -> 0.15 | E34: =Inputs!$B$39*IF($A34>=$G$9,1-lgd,1) -> 0.15 | F34: =Inputs!$B$39*IF($A34>=$G$10,1-lgd,1) -> 0.06 | G34: =Inputs!$B$39*IF($A34>=$G$11,1-lgd,1) -> 0.06 | H34: =Inputs!$B$39*IF($A34>=$G$12,1-lgd,1) -> 0.06 | I34: =Inputs!$B$39*IF($A34>=$G$13,1-lgd,1) -> 0.15 | J34: =Inputs!$B$39*IF($A34>=$G$14,1-lgd,1) -> 0.06 | K34: =Inputs!$B$39*IF($A34>=$G$15,1-lgd,1) -> 0.15 | L34: =SUM(B34:K34) -> 1.05 | M34: =MIN(L34,Inputs!$D$39) -> 0.1 | N34: =MIN(L34-M34,Inputs!$E$39) -> 0.1 | O34: =L34-M34-N34 -> 0.85 | P34: =Inputs!$C$39 -> 1.5
A35: 16 | B35: =Inputs!$B$40*IF($A35>=$G$6,1-lgd,1) -> 0.06 | C35: =Inputs!$B$40*IF($A35>=$G$7,1-lgd,1) -> 0.15 | D35: =Inputs!$B$40*IF($A35>=$G$8,1-lgd,1) -> 0.15 | E35: =Inputs!$B$40*IF($A35>=$G$9,1-lgd,1) -> 0.15 | F35: =Inputs!$B$40*IF($A35>=$G$10,1-lgd,1) -> 0.06 | G35: =Inputs!$B$40*IF($A35>=$G$11,1-lgd,1) -> 0.06 | H35: =Inputs!$B$40*IF($A35>=$G$12,1-lgd,1) -> 0.06 | I35: =Inputs!$B$40*IF($A35>=$G$13,1-lgd,1) -> 0.15 | J35: =Inputs!$B$40*IF($A35>=$G$14,1-lgd,1) -> 0.06 | K35: =Inputs!$B$40*IF($A35>=$G$15,1-lgd,1) -> 0.15 | L35: =SUM(B35:K35) -> 1.05 | M35: =MIN(L35,Inputs!$D$40) -> 0.1 | N35: =MIN(L35-M35,Inputs!$E$40) -> 0.1 | O35: =L35-M35-N35 -> 0.85 | P35: =Inputs!$C$40 -> 1.5
A36: 17 | B36: =Inputs!$B$41*IF($A36>=$G$6,1-lgd,1) -> 0.06 | C36: =Inputs!$B$41*IF($A36>=$G$7,1-lgd,1) -> 0.15 | D36: =Inputs!$B$41*IF($A36>=$G$8,1-lgd,1) -> 0.15 | E36: =Inputs!$B$41*IF($A36>=$G$9,1-lgd,1) -> 0.15 | F36: =Inputs!$B$41*IF($A36>=$G$10,1-lgd,1) -> 0.06 | G36: =Inputs!$B$41*IF($A36>=$G$11,1-lgd,1) -> 0.06 | H36: =Inputs!$B$41*IF($A36>=$G$12,1-lgd,1) -> 0.06 | I36: =Inputs!$B$41*IF($A36>=$G$13,1-lgd,1) -> 0.15 | J36: =Inputs!$B$41*IF($A36>=$G$14,1-lgd,1) -> 0.06 | K36: =Inputs!$B$41*IF($A36>=$G$15,1-lgd,1) -> 0.15 | L36: =SUM(B36:K36) -> 1.05 | M36: =MIN(L36,Inputs!$D$41) -> 0.1 | N36: =MIN(L36-M36,Inputs!$E$41) -> 0.1 | O36: =L36-M36-N36 -> 0.85 | P36: =Inputs!$C$41 -> 1.5
A37: 18 | B37: =Inputs!$B$42*IF($A37>=$G$6,1-lgd,1) -> 0.06 | C37: =Inputs!$B$42*IF($A37>=$G$7,1-lgd,1) -> 0.15 | D37: =Inputs!$B$42*IF($A37>=$G$8,1-lgd,1) -> 0.15 | E37: =Inputs!$B$42*IF($A37>=$G$9,1-lgd,1) -> 0.15 | F37: =Inputs!$B$42*IF($A37>=$G$10,1-lgd,1) -> 0.06 | G37: =Inputs!$B$42*IF($A37>=$G$11,1-lgd,1) -> 0.06 | H37: =Inputs!$B$42*IF($A37>=$G$12,1-lgd,1) -> 0.06 | I37: =Inputs!$B$42*IF($A37>=$G$13,1-lgd,1) -> 0.15 | J37: =Inputs!$B$42*IF($A37>=$G$14,1-lgd,1) -> 0.06 | K37: =Inputs!$B$42*IF($A37>=$G$15,1-lgd,1) -> 0.15 | L37: =SUM(B37:K37) -> 1.05 | M37: =MIN(L37,Inputs!$D$42) -> 0.1 | N37: =MIN(L37-M37,Inputs!$E$42) -> 0.1 | O37: =L37-M37-N37 -> 0.85 | P37: =Inputs!$C$42 -> 1.5
A38: 19 | B38: =Inputs!$B$43*IF($A38>=$G$6,1-lgd,1) -> 0.06 | C38: =Inputs!$B$43*IF($A38>=$G$7,1-lgd,1) -> 0.15 | D38: =Inputs!$B$43*IF($A38>=$G$8,1-lgd,1) -> 0.15 | E38: =Inputs!$B$43*IF($A38>=$G$9,1-lgd,1) -> 0.15 | F38: =Inputs!$B$43*IF($A38>=$G$10,1-lgd,1) -> 0.06 | G38: =Inputs!$B$43*IF($A38>=$G$11,1-lgd,1) -> 0.06 | H38: =Inputs!$B$43*IF($A38>=$G$12,1-lgd,1) -> 0.06 | I38: =Inputs!$B$43*IF($A38>=$G$13,1-lgd,1) -> 0.15 | J38: =Inputs!$B$43*IF($A38>=$G$14,1-lgd,1) -> 0.06 | K38: =Inputs!$B$43*IF($A38>=$G$15,1-lgd,1) -> 0.15 | L38: =SUM(B38:K38) -> 1.05 | M38: =MIN(L38,Inputs!$D$43) -> 0.1 | N38: =MIN(L38-M38,Inputs!$E$43) -> 0.1 | O38: =L38-M38-N38 -> 0.85 | P38: =Inputs!$C$43 -> 1.5
A39: 20 | B39: =Inputs!$B$44*IF($A39>=$G$6,1-lgd,1) -> 4.06 | C39: =Inputs!$B$44*IF($A39>=$G$7,1-lgd,1) -> 10.15 | D39: =Inputs!$B$44*IF($A39>=$G$8,1-lgd,1) -> 10.15 | E39: =Inputs!$B$44*IF($A39>=$G$9,1-lgd,1) -> 4.06 | F39: =Inputs!$B$44*IF($A39>=$G$10,1-lgd,1) -> 4.06 | G39: =Inputs!$B$44*IF($A39>=$G$11,1-lgd,1) -> 4.06 | H39: =Inputs!$B$44*IF($A39>=$G$12,1-lgd,1) -> 4.06 | I39: =Inputs!$B$44*IF($A39>=$G$13,1-lgd,1) -> 10.15 | J39: =Inputs!$B$44*IF($A39>=$G$14,1-lgd,1) -> 4.06 | K39: =Inputs!$B$44*IF($A39>=$G$15,1-lgd,1) -> 10.15 | L39: =SUM(B39:K39) -> 64.96 | M39: =MIN(L39,Inputs!$D$44) -> 20.1 | N39: =MIN(L39-M39,Inputs!$E$44) -> 10.1 | O39: =L39-M39-N39 -> 34.76 | P39: =Inputs!$C$44 -> 101.5
A40: Total | B40: =SUM(B20:B39) -> 5.47 | C40: =SUM(C20:C39) -> 13 | D40: =SUM(D20:D39) -> 13 | E40: =SUM(E20:E39) -> 6.91 | F40: =SUM(F20:F39) -> 5.56 | G40: =SUM(G20:G39) -> 6.28 | H40: =SUM(H20:H39) -> 6.19 | I40: =SUM(I20:I39) -> 13 | ... P40: =SUM(P20:P39) -> 130
A42: Check: pool total for this case on the CashFlows sheet minus the total above (should be 0) | L42: =ROUND(INDEX(CashFlows!$CH$18:$CH$1017,case_number)-L40,9) -> 0

Sheet Random
A1: Fixed random numbers and moment matching
A2: 1000 cases x 10 bonds of independent standard normals, generated once in Python (numpy default_rng, seed 6103) and stored as values, so every recalculation uses the same numbers. They are then de-meaned and moment matched: multiplied by the inverse of the Cholesky factor of their covariance, which gives numbers with means of exactly 0, variances of exactly 1 and no correlation.
B3: Covariance of the initial numbers (population) | M3: Cholesky factor L of that covariance | X3: Inverse of L | AI3: Check: covariance of the moment-matched numbers (identity)
B4: =COVAR($B$18:$B$1017,$B$18:$B$1017) -> 1.0092959 | C4: =COVAR($B$18:$B$1017,$C$18:$C$1017) -> -0.0075252807 | D4: =COVAR($B$18:$B$1017,$D$18:$D$1017) -> -0.0015624279 | E4: =COVAR($B$18:$B$1017,$E$18:$E$1017) -> 0.0070805288 | F4: =COVAR($B$18:$B$1017,$F$18:$F$1017) -> 0.023571375 | G4: =COVAR($B$18:$B$1017,$G$18:$G$1017) -> 0.01507392 | H4: =COVAR($B$18:$B$1017,$H$18:$H$1017) -> 0.02057704 | I4: =COVAR($B$18:$B$1017,$I$18:$I$1017) -> 0.020295584 | J4: =COVAR($B$18:$B$1017,$J$18:$J$1017) -> -0.010252705 | K4: =COVAR($B$18:$B$1017,$K$18:$K$1017) -> -0.0234292 | M4: =SQRT(B4) -> 1.0046372 | N4: 0 | O4: 0 | P4: 0 | Q4: 0 | R4: 0 | S4: 0 | T4: 0 | U4: 0 | V4: 0 | X4: {=MINVERSE(M4:V13)} -> 0.99538421 | Y4: 0 | Z4: 0 | AA4: 0 | AB4: 0 | AC4: 0 | AD4: 0 | AE4: 0 | AF4: 0 | AG4: 0 | AI4: =COVAR($X$18:$X$1017,$X$18:$X$1017) -> 1 | AJ4: =COVAR($X$18:$X$1017,$Y$18:$Y$1017) -> -1.831868e-17 | AK4: =COVAR($X$18:$X$1017,$Z$18:$Z$1017) -> -1.5765167e-17 | AL4: =COVAR($X$18:$X$1017,$AA$18:$AA$1017) -> -8.6874952e-18 | AM4: =COVAR($X$18:$X$1017,$AB$18:$AB$1017) -> -1.3877788e-17 | AN4: =COVAR($X$18:$X$1017,$AC$18:$AC$1017) -> 1.7319479e-17 | AO4: =COVAR($X$18:$X$1017,$AD$18:$AD$1017) -> -2.5757174e-17 | AP4: =COVAR($X$18:$X$1017,$AE$18:$AE$1017) -> 1.7597035e-17 | AQ4: =COVAR($X$18:$X$1017,$AF$18:$AF$1017) -> 3.9135362e-17 | AR4: =COVAR($X$18:$X$1017,$AG$18:$AG$1017) -> 4.2327253e-19
B5: =COVAR($C$18:$C$1017,$B$18:$B$1017) -> -0.0075252807 | C5: =COVAR($C$18:$C$1017,$C$18:$C$1017) -> 1.0286454 | D5: =COVAR($C$18:$C$1017,$D$18:$D$1017) -> 0.0034923397 | E5: =COVAR($C$18:$C$1017,$E$18:$E$1017) -> 0.0062694234 | F5: =COVAR($C$18:$C$1017,$F$18:$F$1017) -> 0.021607608 | G5: =COVAR($C$18:$C$1017,$G$18:$G$1017) -> 0.042956429 | H5: =COVAR($C$18:$C$1017,$H$18:$H$1017) -> -0.052975298 | I5: =COVAR($C$18:$C$1017,$I$18:$I$1017) -> 0.088553723 | J5: =COVAR($C$18:$C$1017,$J$18:$J$1017) -> -0.062365207 | K5: =COVAR($C$18:$C$1017,$K$18:$K$1017) -> 0.016286095 | M5: =B5/$M$4 -> -0.0074905456 | N5: =SQRT(C5-SUMSQ($M5:M5)) -> 1.0141939 | O5: 0 | P5: 0 | Q5: 0 | R5: 0 | S5: 0 | T5: 0 | U5: 0 | V5: 0 | X5: 0.0073516226 | Y5: 0.98600473 | Z5: 0 | AA5: 0 | AB5: 0 | AC5: 0 | AD5: 0 | AE5: 0 | AF5: 0 | AG5: 0 | AI5: =COVAR($Y$18:$Y$1017,$X$18:$X$1017) -> -1.831868e-17 | AJ5: =COVAR($Y$18:$Y$1017,$Y$18:$Y$1017) -> 1 | AK5: =COVAR($Y$18:$Y$1017,$Z$18:$Z$1017) -> 1.4321877e-17 | AL5: =COVAR($Y$18:$Y$1017,$AA$18:$AA$1017) -> -1.1268764e-17 | AM5: =COVAR($Y$18:$Y$1017,$AB$18:$AB$1017) -> -4.2132964e-17 | AN5: =COVAR($Y$18:$Y$1017,$AC$18:$AC$1017) -> -6.5725203e-17 | AO5: =COVAR($Y$18:$Y$1017,$AD$18:$AD$1017) -> 4.2382764e-17 | AP5: =COVAR($Y$18:$Y$1017,$AE$18:$AE$1017) -> 1.2451151e-16 | AQ5: =COVAR($Y$18:$Y$1017,$AF$18:$AF$1017) -> 7.6050277e-18 | AR5: =COVAR($Y$18:$Y$1017,$AG$18:$AG$1017) -> 3.2925052e-17
B6: =COVAR($D$18:$D$1017,$B$18:$B$1017) -> -0.0015624279 | C6: =COVAR($D$18:$D$1017,$C$18:$C$1017) -> 0.0034923397 | D6: =COVAR($D$18:$D$1017,$D$18:$D$1017) -> 1.0013933 | E6: =COVAR($D$18:$D$1017,$E$18:$E$1017) -> 0.034972157 | F6: =COVAR($D$18:$D$1017,$F$18:$F$1017) -> 0.0075113511 | G6: =COVAR($D$18:$D$1017,$G$18:$G$1017) -> 0.0081424253 | H6: =COVAR($D$18:$D$1017,$H$18:$H$1017) -> 0.034026381 | I6: =COVAR($D$18:$D$1017,$I$18:$I$1017) -> 0.020532999 | J6: =COVAR($D$18:$D$1017,$J$18:$J$1017) -> 0.0060919711 | K6: =COVAR($D$18:$D$1017,$K$18:$K$1017) -> 0.070295138 | M6: =B6/$M$4 -> -0.0015552161 | N6: =(C6-SUMPRODUCT($M6:M6,$M5:M5))/N5 -> 0.0034319771 | O6: =SQRT(D6-SUMSQ($M6:N6)) -> 1.0006893 | P6: 0 | Q6: 0 | R6: 0 | S6: 0 | T6: 0 | U6: 0 | V6: 0 | X6: 0.0015217579 | Y6: -0.0033816146 | Z6: 0.99931115 | AA6: 0 | AB6: 0 | AC6: 0 | AD6: 0 | AE6: 0 | AF6: 0 | AG6: 0 | AI6: =COVAR($Z$18:$Z$1017,$X$18:$X$1017) -> -1.5765167e-17 | AJ6: =COVAR($Z$18:$Z$1017,$Y$18:$Y$1017) -> 1.4321877e-17 | AK6: =COVAR($Z$18:$Z$1017,$Z$18:$Z$1017) -> 1 | AL6: =COVAR($Z$18:$Z$1017,$AA$18:$AA$1017) -> -6.3282712e-17 | AM6: =COVAR($Z$18:$Z$1017,$AB$18:$AB$1017) -> -3.1086245e-18 | AN6: =COVAR($Z$18:$Z$1017,$AC$18:$AC$1017) -> 3.7747583e-17 | AO6: =COVAR($Z$18:$Z$1017,$AD$18:$AD$1017) -> 2.4202862e-17 | AP6: =COVAR($Z$18:$Z$1017,$AE$18:$AE$1017) -> 9.7699626e-18 | AQ6: =COVAR($Z$18:$Z$1017,$AF$18:$AF$1017) -> 1.9095836e-17 | AR6: =COVAR($Z$18:$Z$1017,$AG$18:$AG$1017) -> 6.0562666e-17
B7: =COVAR($E$18:$E$1017,$B$18:$B$1017) -> 0.0070805288 | C7: =COVAR($E$18:$E$1017,$C$18:$C$1017) -> 0.0062694234 | D7: =COVAR($E$18:$E$1017,$D$18:$D$1017) -> 0.034972157 | E7: =COVAR($E$18:$E$1017,$E$18:$E$1017) -> 0.98057864 | F7: =COVAR($E$18:$E$1017,$F$18:$F$1017) -> 0.019587025 | G7: =COVAR($E$18:$E$1017,$G$18:$G$1017) -> 0.01930415 | H7: =COVAR($E$18:$E$1017,$H$18:$H$1017) -> 0.028531027 | I7: =COVAR($E$18:$E$1017,$I$18:$I$1017) -> 0.024922848 | J7: =COVAR($E$18:$E$1017,$J$18:$J$1017) -> -0.052906483 | K7: =COVAR($E$18:$E$1017,$K$18:$K$1017) -> -0.028253352 | M7: =B7/$M$4 -> 0.0070478466 | N7: =(C7-SUMPRODUCT($M7:M7,$M5:M5))/N5 -> 0.0062337345 | O7: =(D7-SUMPRODUCT($M7:N7,$M6:N6))/O6 -> 0.034937641 | P7: =SQRT(E7-SUMSQ($M7:O7)) -> 0.98958045 | Q7: 0 | R7: 0 | S7: 0 | T7: 0 | U7: 0 | V7: 0 | X7: -0.0071892184 | Y7: -0.0060918201 | Z7: -0.035281188 | AA7: 1.0105293 | AB7: 0 | AC7: 0 | AD7: 0 | AE7: 0 | AF7: 0 | AG7: 0 | AI7: =COVAR($AA$18:$AA$1017,$X$18:$X$1017) -> -8.6874952e-18 | AJ7: =COVAR($AA$18:$AA$1017,$Y$18:$Y$1017) -> -1.1268764e-17 | AK7: =COVAR($AA$18:$AA$1017,$Z$18:$Z$1017) -> -6.3282712e-17 | AL7: =COVAR($AA$18:$AA$1017,$AA$18:$AA$1017) -> 1 | AM7: =COVAR($AA$18:$AA$1017,$AB$18:$AB$1017) -> -9.4479979e-17 | AN7: =COVAR($AA$18:$AA$1017,$AC$18:$AC$1017) -> -3.9301895e-17 | AO7: =COVAR($AA$18:$AA$1017,$AD$18:$AD$1017) -> -6.1450844e-17 | AP7: =COVAR($AA$18:$AA$1017,$AE$18:$AE$1017) -> -9.8809849e-17 | AQ7: =COVAR($AA$18:$AA$1017,$AF$18:$AF$1017) -> 6.2561067e-17 | AR7: =COVAR($AA$18:$AA$1017,$AG$18:$AG$1017) -> 8.1254448e-17
B8: =COVAR($F$18:$F$1017,$B$18:$B$1017) -> 0.023571375 | C8: =COVAR($F$18:$F$1017,$C$18:$C$1017) -> 0.021607608 | D8: =COVAR($F$18:$F$1017,$D$18:$D$1017) -> 0.0075113511 | E8: =COVAR($F$18:$F$1017,$E$18:$E$1017) -> 0.019587025 | F8: =COVAR($F$18:$F$1017,$F$18:$F$1017) -> 1.0388062 | G8: =COVAR($F$18:$F$1017,$G$18:$G$1017) -> -0.012111641 | H8: =COVAR($F$18:$F$1017,$H$18:$H$1017) -> -0.0014115587 | I8: =COVAR($F$18:$F$1017,$I$18:$I$1017) -> -0.010611901 | J8: =COVAR($F$18:$F$1017,$J$18:$J$1017) -> -0.041997899 | K8: =COVAR($F$18:$F$1017,$K$18:$K$1017) -> 0.045961781 | M8: =B8/$M$4 -> 0.023462575 | N8: =(C8-SUMPRODUCT($M8:M8,$M5:M5))/N5 -> 0.021478492 | O8: =(D8-SUMPRODUCT($M8:N8,$M6:N6))/O6 -> 0.0074689782 | P8: =(E8-SUMPRODUCT($M8:O8,$M7:O7))/P7 -> 0.019227163 | Q8: =SQRT(F8-SUMSQ($M8:P8)) -> 1.0185131 | R8: 0 | S8: 0 | T8: 0 | U8: 0 | V8: 0 | X8: -0.02296025 | Y8: -0.020653155 | Z8: -0.0066621391 | AA8: -0.019076447 | AB8: 0.9818234 | AC8: 0 | AD8: 0 | AE8: 0 | AF8: 0 | AG8: 0 | AI8: =COVAR($AB$18:$AB$1017,$X$18:$X$1017) -> -1.3877788e-17 | AJ8: =COVAR($AB$18:$AB$1017,$Y$18:$Y$1017) -> -4.2132964e-17 | AK8: =COVAR($AB$18:$AB$1017,$Z$18:$Z$1017) -> -3.1086245e-18 | AL8: =COVAR($AB$18:$AB$1017,$AA$18:$AA$1017) -> -9.4479979e-17 | AM8: =COVAR($AB$18:$AB$1017,$AB$18:$AB$1017) -> 1 | AN8: =COVAR($AB$18:$AB$1017,$AC$18:$AC$1017) -> -3.9968029e-18 | AO8: =COVAR($AB$18:$AB$1017,$AD$18:$AD$1017) -> 2.9976022e-18 | AP8: =COVAR($AB$18:$AB$1017,$AE$18:$AE$1017) -> -9.547918e-18 | AQ8: =COVAR($AB$18:$AB$1017,$AF$18:$AF$1017) -> -4.773959e-17 | AR8: =COVAR($AB$18:$AB$1017,$AG$18:$AG$1017) -> -3.494427e-17
B9: =COVAR($G$18:$G$1017,$B$18:$B$1017) -> 0.01507392 | C9: =COVAR($G$18:$G$1017,$C$18:$C$1017) -> 0.042956429 | D9: =COVAR($G$18:$G$1017,$D$18:$D$1017) -> 0.0081424253 | E9: =COVAR($G$18:$G$1017,$E$18:$E$1017) -> 0.01930415 | F9: =COVAR($G$18:$G$1017,$F$18:$F$1017) -> -0.012111641 | G9: =COVAR($G$18:$G$1017,$G$18:$G$1017) -> 1.0256948 | H9: =COVAR($G$18:$G$1017,$H$18:$H$1017) -> -0.0011387811 | I9: =COVAR($G$18:$G$1017,$I$18:$I$1017) -> 0.052862551 | J9: =COVAR($G$18:$G$1017,$J$18:$J$1017) -> -0.060624425 | K9: =COVAR($G$18:$G$1017,$K$18:$K$1017) -> -0.010844416 | M9: =B9/$M$4 -> 0.015004342 | N9: =(C9-SUMPRODUCT($M9:M9,$M5:M5))/N5 -> 0.04246606 | O9: =(D9-SUMPRODUCT($M9:N9,$M6:N6))/O6 -> 0.0080144931 | P9: =(E9-SUMPRODUCT($M9:O9,$M7:O7))/P7 -> 0.018850082 | Q9: =(F9-SUMPRODUCT($M9:P9,$M8:P8))/Q8 -> -0.01354728 | R9: =SQRT(G9-SUMSQ($M9:Q9)) -> 1.0114659 | S9: 0 | T9: 0 | U9: 0 | V9: 0 | X9: -0.015260038 | Y9: -0.04153338 | Z9: -0.0073498999 | AA9: -0.019088131 | AB9: 0.013150257 | AC9: 0.9886641 | AD9: 0 | AE9: 0 | AF9: 0 | AG9: 0 | AI9: =COVAR($AC$18:$AC$1017,$X$18:$X$1017) -> 1.7319479e-17 | AJ9: =COVAR($AC$18:$AC$1017,$Y$18:$Y$1017) -> -6.5725203e-17 | AK9: =COVAR($AC$18:$AC$1017,$Z$18:$Z$1017) -> 3.7747583e-17 | AL9: =COVAR($AC$18:$AC$1017,$AA$18:$AA$1017) -> -3.9301895e-17 | AM9: =COVAR($AC$18:$AC$1017,$AB$18:$AB$1017) -> -3.9968029e-18 | AN9: =COVAR($AC$18:$AC$1017,$AC$18:$AC$1017) -> 1 | AO9: =COVAR($AC$18:$AC$1017,$AD$18:$AD$1017) -> -1.6653345e-18 | AP9: =COVAR($AC$18:$AC$1017,$AE$18:$AE$1017) -> -8.3266727e-17 | AQ9: =COVAR($AC$18:$AC$1017,$AF$18:$AF$1017) -> -2.4646951e-17 | AR9: =COVAR($AC$18:$AC$1017,$AG$18:$AG$1017) -> -1.8735014e-17
B10: =COVAR($H$18:$H$1017,$B$18:$B$1017) -> 0.02057704 | C10: =COVAR($H$18:$H$1017,$C$18:$C$1017) -> -0.052975298 | D10: =COVAR($H$18:$H$1017,$D$18:$D$1017) -> 0.034026381 | E10: =COVAR($H$18:$H$1017,$E$18:$E$1017) -> 0.028531027 | F10: =COVAR($H$18:$H$1017,$F$18:$F$1017) -> -0.0014115587 | G10: =COVAR($H$18:$H$1017,$G$18:$G$1017) -> -0.0011387811 | H10: =COVAR($H$18:$H$1017,$H$18:$H$1017) -> 1.0053972 | I10: =COVAR($H$18:$H$1017,$I$18:$I$1017) -> 0.0064358816 | J10: =COVAR($H$18:$H$1017,$J$18:$J$1017) -> 0.0023051558 | K10: =COVAR($H$18:$H$1017,$K$18:$K$1017) -> 0.024469756 | M10: =B10/$M$4 -> 0.020482061 | N10: =(C10-SUMPRODUCT($M10:M10,$M5:M5))/N5 -> -0.05208262 | O10: =(D10-SUMPRODUCT($M10:N10,$M6:N6))/O6 -> 0.034213397 | P10: =(E10-SUMPRODUCT($M10:O10,$M7:O7))/P7 -> 0.027805729 | Q10: =(F10-SUMPRODUCT($M10:P10,$M8:P8))/Q8 -> -0.0015352074 | R10: =(G10-SUMPRODUCT($M10:Q10,$M9:Q9))/R9 -> -5.2892081e-05 | S10: =SQRT(H10-SUMSQ($M10:R10)) -> 1.0001595 | T10: 0 | U10: 0 | V10: 0 | X10: -0.019889675 | Y10: 0.05159666 | Z10: -0.033214129 | AA10: -0.028124313 | AB10: 0.0015077576 | AC10: 5.2284163e-05 | AD10: 0.99984053 | AE10: 0 | AF10: 0 | AG10: 0 | AI10: =COVAR($AD$18:$AD$1017,$X$18:$X$1017) -> -2.5757174e-17 | AJ10: =COVAR($AD$18:$AD$1017,$Y$18:$Y$1017) -> 4.2382764e-17 | AK10: =COVAR($AD$18:$AD$1017,$Z$18:$Z$1017) -> 2.4202862e-17 | AL10: =COVAR($AD$18:$AD$1017,$AA$18:$AA$1017) -> -6.1450844e-17 | AM10: =COVAR($AD$18:$AD$1017,$AB$18:$AB$1017) -> 2.9976022e-18 | AN10: =COVAR($AD$18:$AD$1017,$AC$18:$AC$1017) -> -1.6653345e-18 | AO10: =COVAR($AD$18:$AD$1017,$AD$18:$AD$1017) -> 1 | AP10: =COVAR($AD$18:$AD$1017,$AE$18:$AE$1017) -> 1.5654145e-17 | AQ10: =COVAR($AD$18:$AD$1017,$AF$18:$AF$1017) -> 1.8873791e-17 | AR10: =COVAR($AD$18:$AD$1017,$AG$18:$AG$1017) -> 6.5225603e-18
B11: =COVAR($I$18:$I$1017,$B$18:$B$1017) -> 0.020295584 | C11: =COVAR($I$18:$I$1017,$C$18:$C$1017) -> 0.088553723 | D11: =COVAR($I$18:$I$1017,$D$18:$D$1017) -> 0.020532999 | E11: =COVAR($I$18:$I$1017,$E$18:$E$1017) -> 0.024922848 | F11: =COVAR($I$18:$I$1017,$F$18:$F$1017) -> -0.010611901 | G11: =COVAR($I$18:$I$1017,$G$18:$G$1017) -> 0.052862551 | H11: =COVAR($I$18:$I$1017,$H$18:$H$1017) -> 0.0064358816 | I11: =COVAR($I$18:$I$1017,$I$18:$I$1017) -> 0.99533869 | J11: =COVAR($I$18:$I$1017,$J$18:$J$1017) -> 0.002067126 | K11: =COVAR($I$18:$I$1017,$K$18:$K$1017) -> -0.01220048 | M11: =B11/$M$4 -> 0.020201904 | N11: =(C11-SUMPRODUCT($M11:M11,$M5:M5))/N5 -> 0.087463595 | O11: =(D11-SUMPRODUCT($M11:N11,$M6:N6))/O6 -> 0.020250285 | P11: =(E11-SUMPRODUCT($M11:O11,$M7:O7))/P7 -> 0.023775476 | Q11: =(F11-SUMPRODUCT($M11:P11,$M8:P8))/Q8 -> -0.013326151 | R11: =(G11-SUMPRODUCT($M11:Q11,$M9:Q9))/R9 -> 0.047509464 | S11: =(H11-SUMPRODUCT($M11:R11,$M10:R10))/S10 -> 0.0092040991 | T11: =SQRT(I11-SUMSQ($M11:S11)) -> 0.99185982 | U11: 0 | V11: 0 | X11: -0.020173671 | Y11: -0.085499082 | Z11: -0.018985942 | AA11: -0.023304003 | AB11: 0.012547426 | AC11: -0.047356876 | AD11: -0.0092781572 | AE11: 1.008207 | AF11: 0 | AG11: 0 | AI11: =COVAR($AE$18:$AE$1017,$X$18:$X$1017) -> 1.7597035e-17 | AJ11: =COVAR($AE$18:$AE$1017,$Y$18:$Y$1017) -> 1.2451151e-16 | AK11: =COVAR($AE$18:$AE$1017,$Z$18:$Z$1017) -> 9.7699626e-18 | AL11: =COVAR($AE$18:$AE$1017,$AA$18:$AA$1017) -> -9.8809849e-17 | AM11: =COVAR($AE$18:$AE$1017,$AB$18:$AB$1017) -> -9.547918e-18 | AN11: =COVAR($AE$18:$AE$1017,$AC$18:$AC$1017) -> -8.3266727e-17 | AO11: =COVAR($AE$18:$AE$1017,$AD$18:$AD$1017) -> 1.5654145e-17 | AP11: =COVAR($AE$18:$AE$1017,$AE$18:$AE$1017) -> 1 | AQ11: =COVAR($AE$18:$AE$1017,$AF$18:$AF$1017) -> -5.1958438e-17 | AR11: =COVAR($AE$18:$AE$1017,$AG$18:$AG$1017) -> -6.6613381e-18
B12: =COVAR($J$18:$J$1017,$B$18:$B$1017) -> -0.010252705 | C12: =COVAR($J$18:$J$1017,$C$18:$C$1017) -> -0.062365207 | D12: =COVAR($J$18:$J$1017,$D$18:$D$1017) -> 0.0060919711 | E12: =COVAR($J$18:$J$1017,$E$18:$E$1017) -> -0.052906483 | F12: =COVAR($J$18:$J$1017,$F$18:$F$1017) -> -0.041997899 | G12: =COVAR($J$18:$J$1017,$G$18:$G$1017) -> -0.060624425 | H12: =COVAR($J$18:$J$1017,$H$18:$H$1017) -> 0.0023051558 | I12: =COVAR($J$18:$J$1017,$I$18:$I$1017) -> 0.002067126 | J12: =COVAR($J$18:$J$1017,$J$18:$J$1017) -> 0.95791619 | K12: =COVAR($J$18:$J$1017,$K$18:$K$1017) -> -0.029365866 | M12: =B12/$M$4 -> -0.010205381 | N12: =(C12-SUMPRODUCT($M12:M12,$M5:M5))/N5 -> -0.061567763 | O12: =(D12-SUMPRODUCT($M12:N12,$M6:N6))/O6 -> 0.0062830676 | P12: =(E12-SUMPRODUCT($M12:O12,$M7:O7))/P7 -> -0.053224855 | Q12: =(F12-SUMPRODUCT($M12:P12,$M8:P8))/Q8 -> -0.038742394 | R12: =(G12-SUMPRODUCT($M12:Q12,$M9:Q9))/R9 -> -0.056777671 | S12: =(H12-SUMPRODUCT($M12:R12,$M10:R10))/S10 -> 0.0005100014 | T12: =(I12-SUMPRODUCT($M12:S12,$M11:S11))/T11 -> 0.011062995 | U12: =SQRT(J12-SUMSQ($M12:T12)) -> 0.97278043 | V12: 0 | X12: 0.0089393784 | Y12: 0.059791866 | Z12: -0.008845791 | AA12: 0.053696168 | AB12: 0.03972659 | AC12: 0.058243284 | AD12: -0.00041867193 | AE12: -0.011465885 | AF12: 1.0279812 | AG12: 0 | AI12: =COVAR($AF$18:$AF$1017,$X$18:$X$1017) -> 3.9135362e-17 | AJ12: =COVAR($AF$18:$AF$1017,$Y$18:$Y$1017) -> 7.6050277e-18 | AK12: =COVAR($AF$18:$AF$1017,$Z$18:$Z$1017) -> 1.9095836e-17 | AL12: =COVAR($AF$18:$AF$1017,$AA$18:$AA$1017) -> 6.2561067e-17 | AM12: =COVAR($AF$18:$AF$1017,$AB$18:$AB$1017) -> -4.773959e-17 | AN12: =COVAR($AF$18:$AF$1017,$AC$18:$AC$1017) -> -2.4646951e-17 | AO12: =COVAR($AF$18:$AF$1017,$AD$18:$AD$1017) -> 1.8873791e-17 | AP12: =COVAR($AF$18:$AF$1017,$AE$18:$AE$1017) -> -5.1958438e-17 | AQ12: =COVAR($AF$18:$AF$1017,$AF$18:$AF$1017) -> 1 | AR12: =COVAR($AF$18:$AF$1017,$AG$18:$AG$1017) -> -3.8774539e-17
B13: =COVAR($K$18:$K$1017,$B$18:$B$1017) -> -0.0234292 | C13: =COVAR($K$18:$K$1017,$C$18:$C$1017) -> 0.016286095 | D13: =COVAR($K$18:$K$1017,$D$18:$D$1017) -> 0.070295138 | E13: =COVAR($K$18:$K$1017,$E$18:$E$1017) -> -0.028253352 | F13: =COVAR($K$18:$K$1017,$F$18:$F$1017) -> 0.045961781 | G13: =COVAR($K$18:$K$1017,$G$18:$G$1017) -> -0.010844416 | H13: =COVAR($K$18:$K$1017,$H$18:$H$1017) -> 0.024469756 | I13: =COVAR($K$18:$K$1017,$I$18:$I$1017) -> -0.01220048 | J13: =COVAR($K$18:$K$1017,$J$18:$J$1017) -> -0.029365866 | K13: =COVAR($K$18:$K$1017,$K$18:$K$1017) -> 1.0111057 | M13: =B13/$M$4 -> -0.023321055 | N13: =(C13-SUMPRODUCT($M13:M13,$M5:M5))/N5 -> 0.015885924 | O13: =(D13-SUMPRODUCT($M13:N13,$M6:N6))/O6 -> 0.070155988 | P13: =(E13-SUMPRODUCT($M13:O13,$M7:O7))/P7 -> -0.030961709 | Q13: =(F13-SUMPRODUCT($M13:P13,$M8:P8))/Q8 -> 0.045398591 | R13: =(G13-SUMPRODUCT($M13:Q13,$M9:Q9))/R9 -> -0.01041332 | S13: =(H13-SUMPRODUCT($M13:R13,$M10:R10))/S10 -> 0.024300708 | T13: =(I13-SUMPRODUCT($M13:S13,$M11:S11))/T11 -> -0.01303338 | U13: =(J13-SUMPRODUCT($M13:T13,$M12:T12))/U12 -> -0.030238202 | V13: =SQRT(K13-SUMSQ($M13:U13)) -> 1.0002924 | X13: 0.024134384 | Y13: -0.015665444 | Z13: -0.070661259 | AA13: 0.033948447 | AB13: -0.043095705 | AC13: 0.011434614 | AD13: -0.024423278 | AE13: 0.012789898 | AF13: 0.031075219 | AG13: 0.99970772 | AI13: =COVAR($AG$18:$AG$1017,$X$18:$X$1017) -> 4.2327253e-19 | AJ13: =COVAR($AG$18:$AG$1017,$Y$18:$Y$1017) -> 3.2925052e-17 | AK13: =COVAR($AG$18:$AG$1017,$Z$18:$Z$1017) -> 6.0562666e-17 | AL13: =COVAR($AG$18:$AG$1017,$AA$18:$AA$1017) -> 8.1254448e-17 | AM13: =COVAR($AG$18:$AG$1017,$AB$18:$AB$1017) -> -3.494427e-17 | AN13: =COVAR($AG$18:$AG$1017,$AC$18:$AC$1017) -> -1.8735014e-17 | AO13: =COVAR($AG$18:$AG$1017,$AD$18:$AD$1017) -> 6.5225603e-18 | AP13: =COVAR($AG$18:$AG$1017,$AE$18:$AE$1017) -> -6.6613381e-18 | AQ13: =COVAR($AG$18:$AG$1017,$AF$18:$AF$1017) -> -3.8774539e-17 | AR13: =COVAR($AG$18:$AG$1017,$AG$18:$AG$1017) -> 1
A15: Mean | B15: =AVERAGE($B$18:$B$1017) -> 0.017697198 | C15: =AVERAGE($C$18:$C$1017) -> -0.0060295035 | D15: =AVERAGE($D$18:$D$1017) -> 0.033038951 | E15: =AVERAGE($E$18:$E$1017) -> -0.067234436 | F15: =AVERAGE($F$18:$F$1017) -> -0.017214866 | G15: =AVERAGE($G$18:$G$1017) -> -0.037462411 | H15: =AVERAGE($H$18:$H$1017) -> -0.012345434 | I15: =AVERAGE($I$18:$I$1017) -> 0.03057344 | J15: =AVERAGE($J$18:$J$1017) -> -0.013934566 | K15: =AVERAGE($K$18:$K$1017) -> -0.010130081 | M15: =AVERAGE($M$18:$M$1017) -> 3.6248782e-17 | N15: =AVERAGE($N$18:$N$1017) -> -2.2759572e-17 | O15: =AVERAGE($O$18:$O$1017) -> -3.2418512e-17 | P15: =AVERAGE($P$18:$P$1017) -> 8.2156504e-18 | Q15: =AVERAGE($Q$18:$Q$1017) -> 0 | R15: =AVERAGE($R$18:$R$1017) -> -3.3084646e-17 | S15: =AVERAGE($S$18:$S$1017) -> 1.6431301e-17 | T15: =AVERAGE($T$18:$T$1017) -> -2.6645353e-17 | U15: =AVERAGE($U$18:$U$1017) -> -6.5725203e-17 | V15: =AVERAGE($V$18:$V$1017) -> 3.0253577e-17 | X15: =AVERAGE($X$18:$X$1017) -> 3.9190873e-17 | Y15: =AVERAGE($Y$18:$Y$1017) -> -6.8278716e-18 | Z15: =AVERAGE($Z$18:$Z$1017) -> 4.8849813e-18 | AA15: =AVERAGE($AA$18:$AA$1017) -> -2.220446e-18 | AB15: =AVERAGE($AB$18:$AB$1017) -> -1.6653345e-17 | AC15: =AVERAGE($AC$18:$AC$1017) -> -4.3520743e-17 | AD15: =AVERAGE($AD$18:$AD$1017) -> 1.8873791e-17 | AE15: =AVERAGE($AE$18:$AE$1017) -> -2.6201263e-17 | AF15: =AVERAGE($AF$18:$AF$1017) -> -5.7731597e-17 | AG15: =AVERAGE($AG$18:$AG$1017) -> 1.1518564e-17
B16: Initial random normals | M16: De-meaned (initial number minus its column mean) | X16: Moment matched = de-meaned x inverse of L (the numbers the model uses)
A17: Case | B17: Bond 1 | C17: Bond 2 | D17: Bond 3 | E17: Bond 4 | F17: Bond 5 | G17: Bond 6 | H17: Bond 7 | I17: Bond 8 | J17: Bond 9 | K17: Bond 10 | M17: Bond 1 | N17: Bond 2 | O17: Bond 3 | P17: Bond 4 | Q17: Bond 5 | R17: Bond 6 | S17: Bond 7 | T17: Bond 8 | U17: Bond 9 | V17: Bond 10 | X17: Bond 1 | Y17: Bond 2 | Z17: Bond 3 | AA17: Bond 4 | AB17: Bond 5 | AC17: Bond 6 | AD17: Bond 7 | AE17: Bond 8 | AF17: Bond 9 | AG17: Bond 10
A18: 1 | B18: -0.38920512 | C18: 1.1578214 | D18: 0.094403827 | E18: 0.34719004 | F18: 1.1101905 | G18: 0.65847745 | H18: 1.0467667 | I18: -0.47334846 | J18: -0.65241813 | K18: -0.11150449 | M18: =B18-B$15 -> -0.40690232 | N18: =C18-C$15 -> 1.1638509 | O18: =D18-D$15 -> 0.061364877 | P18: =E18-E$15 -> 0.41442448 | Q18: =F18-F$15 -> 1.1274054 | R18: =G18-G$15 -> 0.69593986 | S18: =H18-H$15 -> 1.0591121 | T18: =I18-I$15 -> -0.5039219 | ... V18: =K18-K$15 -> -0.10137441 | X18: =SUMPRODUCT($M18:$V18,$X$4:$AG$4) -> -0.40502414 | Y18: =SUMPRODUCT($M18:$V18,$X$5:$AG$5) -> 1.1445711 | Z18: =SUMPRODUCT($M18:$V18,$X$6:$AG$6) -> 0.056767703 | AA18: =SUMPRODUCT($M18:$V18,$X$7:$AG$7) -> 0.41245837 | AB18: =SUMPRODUCT($M18:$V18,$X$8:$AG$8) -> 1.0839038 | AC18: =SUMPRODUCT($M18:$V18,$X$9:$AG$9) -> 0.65238549 | AD18: =SUMPRODUCT($M18:$V18,$X$10:$AG$10) -> 1.1151299 | AE18: =SUMPRODUCT($M18:$V18,$X$11:$AG$11) -> -0.63881799 | AF18: =SUMPRODUCT($M18:$V18,$X$12:$AG$12) -> -0.47803127 | AG18: =SUMPRODUCT($M18:$V18,$X$13:$AG$13) -> -0.21244605
A19: 2 | B19: -0.74367182 | C19: 1.2128351 | D19: -0.52110702 | E19: 0.86518459 | F19: 0.49348088 | G19: 0.54080648 | H19: 0.11461121 | I19: 0.80470891 | J19: 0.65395696 | K19: 0.21914285 | M19: =B19-B$15 -> -0.76136902 | N19: =C19-C$15 -> 1.2188647 | O19: =D19-D$15 -> -0.55414597 | P19: =E19-E$15 -> 0.93241903 | Q19: =F19-F$15 -> 0.51069575 | R19: =G19-G$15 -> 0.57826889 | S19: =H19-H$15 -> 0.12695665 | T19: =I19-I$15 -> 0.77413547 | ... V19: =K19-K$15 -> 0.22927293 | X19: =SUMPRODUCT($M19:$V19,$X$4:$AG$4) -> -0.75785471 | Y19: =SUMPRODUCT($M19:$V19,$X$5:$AG$5) -> 1.196209 | Z19: =SUMPRODUCT($M19:$V19,$X$6:$AG$6) -> -0.55904459 | AA19: =SUMPRODUCT($M19:$V19,$X$7:$AG$7) -> 0.95983618 | AB19: =SUMPRODUCT($M19:$V19,$X$8:$AG$8) -> 0.47962541 | AC19: =SUMPRODUCT($M19:$V19,$X$9:$AG$9) -> 0.52569921 | AD19: =SUMPRODUCT($M19:$V19,$X$10:$AG$10) -> 0.1979512 | AE19: =SUMPRODUCT($M19:$V19,$X$11:$AG$11) -> 0.65827346 | AF19: =SUMPRODUCT($M19:$V19,$X$12:$AG$12) -> 0.85266033 | AG19: =SUMPRODUCT($M19:$V19,$X$13:$AG$13) -> 0.2747063
A20: 3 | B20: 1.0929463 | C20: -1.0385714 | D20: 0.38965042 | E20: -0.49165919 | F20: -0.70360164 | G20: -0.18083038 | H20: -0.79099469 | I20: 0.12244058 | J20: -0.21931383 | K20: -0.47094783 | M20: =B20-B$15 -> 1.0752491 | N20: =C20-C$15 -> -1.0325419 | O20: =D20-D$15 -> 0.35661147 | P20: =E20-E$15 -> -0.42442475 | Q20: =F20-F$15 -> -0.68638677 | R20: =G20-G$15 -> -0.14336797 | S20: =H20-H$15 -> -0.77864926 | T20: =I20-I$15 -> 0.091867136 | ... V20: =K20-K$15 -> -0.46081775 | X20: =SUMPRODUCT($M20:$V20,$X$4:$AG$4) -> 1.070286 | Y20: =SUMPRODUCT($M20:$V20,$X$5:$AG$5) -> -1.0101864 | Z20: =SUMPRODUCT($M20:$V20,$X$6:$AG$6) -> 0.36149375 | AA20: =SUMPRODUCT($M20:$V20,$X$7:$AG$7) -> -0.44291545 | AB20: =SUMPRODUCT($M20:$V20,$X$8:$AG$8) -> -0.67155261 | AC20: =SUMPRODUCT($M20:$V20,$X$9:$AG$9) -> -0.1188119 | AD20: =SUMPRODUCT($M20:$V20,$X$10:$AG$10) -> -0.85413744 | AE20: =SUMPRODUCT($M20:$V20,$X$11:$AG$11) -> 0.16773245 | AF20: =SUMPRODUCT($M20:$V20,$X$12:$AG$12) -> -0.32554143 | AG20: =SUMPRODUCT($M20:$V20,$X$13:$AG$13) -> -0.41641364
A21: 4 | B21: -0.43419587 | C21: 1.9155 | D21: -0.9390708 | E21: -0.40533839 | F21: -0.050325829 | G21: 1.3117309 | H21: -0.8812356 | I21: -1.6061502 | J21: -0.91029713 | K21: -1.0652618 | M21: =B21-B$15 -> -0.45189307 | N21: =C21-C$15 -> 1.9215296 | O21: =D21-D$15 -> -0.97210975 | P21: =E21-E$15 -> -0.33810395 | Q21: =F21-F$15 -> -0.033110963 | R21: =G21-G$15 -> 1.3491933 | S21: =H21-H$15 -> -0.86889016 | T21: =I21-I$15 -> -1.6367237 | ... V21: =K21-K$15 -> -1.0551317 | X21: =SUMPRODUCT($M21:$V21,$X$4:$AG$4) -> -0.44980723 | Y21: =SUMPRODUCT($M21:$V21,$X$5:$AG$5) -> 1.8913151 | Z21: =SUMPRODUCT($M21:$V21,$X$6:$AG$6) -> -0.97862565 | AA21: =SUMPRODUCT($M21:$V21,$X$7:$AG$7) -> -0.31582361 | AB21: =SUMPRODUCT($M21:$V21,$X$8:$AG$8) -> -0.048893034 | AC21: =SUMPRODUCT($M21:$V21,$X$9:$AG$9) -> 1.2741505 | AD21: =SUMPRODUCT($M21:$V21,$X$10:$AG$10) -> -0.71880175 | AE21: =SUMPRODUCT($M21:$V21,$X$11:$AG$11) -> -1.8352407 | AF21: =SUMPRODUCT($M21:$V21,$X$12:$AG$12) -> -0.72375115 | AG21: =SUMPRODUCT($M21:$V21,$X$13:$AG$13) -> -1.0493313
A22: 5 | B22: -1.8599871 | C22: 0.75061757 | D22: 0.2224588 | E22: -0.78341897 | F22: -1.5263177 | G22: -0.78531154 | H22: -0.83463465 | I22: -0.079703706 | J22: -0.83237702 | K22: 0.28584576 | M22: =B22-B$15 -> -1.8776843 | N22: =C22-C$15 -> 0.75664707 | O22: =D22-D$15 -> 0.18941985 | P22: =E22-E$15 -> -0.71618453 | Q22: =F22-F$15 -> -1.5091029 | R22: =G22-G$15 -> -0.74784913 | S22: =H22-H$15 -> -0.82228921 | T22: =I22-I$15 -> -0.11027715 | ... V22: =K22-K$15 -> 0.29597584 | X22: =SUMPRODUCT($M22:$V22,$X$4:$AG$4) -> -1.8690173 | Y22: =SUMPRODUCT($M22:$V22,$X$5:$AG$5) -> 0.73225356 | Z22: =SUMPRODUCT($M22:$V22,$X$6:$AG$6) -> 0.18387329 | AA22: =SUMPRODUCT($M22:$V22,$X$7:$AG$7) -> -0.72151866 | AB22: =SUMPRODUCT($M22:$V22,$X$8:$AG$8) -> -1.4417872 | AC22: =SUMPRODUCT($M22:$V22,$X$9:$AG$9) -> -0.74971084 | AD22: =SUMPRODUCT($M22:$V22,$X$10:$AG$10) -> -0.73423477 | AE22: =SUMPRODUCT($M22:$V22,$X$11:$AG$11) -> -0.10079161 | AF22: =SUMPRODUCT($M22:$V22,$X$12:$AG$12) -> -0.95491939 | AG22: =SUMPRODUCT($M22:$V22,$X$13:$AG$13) -> 0.25074514
A23: 6 | B23: -0.98899926 | C23: 0.84004433 | D23: -0.01239904 | E23: -0.22507499 | F23: -0.527264 | G23: 1.5757522 | H23: 2.1505611 | I23: -1.1115642 | J23: -0.28865514 | K23: -1.1891091 | M23: =B23-B$15 -> -1.0066965 | N23: =C23-C$15 -> 0.84607383 | O23: =D23-D$15 -> -0.045437991 | P23: =E23-E$15 -> -0.15784055 | Q23: =F23-F$15 -> -0.51004913 | R23: =G23-G$15 -> 1.6132146 | S23: =H23-H$15 -> 2.1629065 | T23: =I23-I$15 -> -1.1421376 | ... V23: =K23-K$15 -> -1.1789791 | X23: =SUMPRODUCT($M23:$V23,$X$4:$AG$4) -> -1.0020498 | Y23: =SUMPRODUCT($M23:$V23,$X$5:$AG$5) -> 0.82683195 | Z23: =SUMPRODUCT($M23:$V23,$X$6:$AG$6) -> -0.049799734 | AA23: =SUMPRODUCT($M23:$V23,$X$7:$AG$7) -> -0.15581616 | AB23: =SUMPRODUCT($M23:$V23,$X$8:$AG$8) -> -0.49182451 | AC23: =SUMPRODUCT($M23:$V23,$X$9:$AG$9) -> 1.5717889 | AD23: =SUMPRODUCT($M23:$V23,$X$10:$AG$10) -> 2.2315027 | AE23: =SUMPRODUCT($M23:$V23,$X$11:$AG$11) -> -1.3018643 | AF23: =SUMPRODUCT($M23:$V23,$X$12:$AG$12) -> -0.16300552 | AG23: =SUMPRODUCT($M23:$V23,$X$13:$AG$13) -> -1.253875
A24: 7 | B24: 0.1824142 | C24: 2.5256254 | D24: 2.4366612 | E24: 0.065815591 | F24: 0.04363933 | G24: -0.97949866 | H24: -1.165684 | I24: 0.27741593 | J24: 0.57217075 | K24: 0.63146098 | M24: =B24-B$15 -> 0.164717 | N24: =C24-C$15 -> 2.5316549 | O24: =D24-D$15 -> 2.4036222 | P24: =E24-E$15 -> 0.13305003 | Q24: =F24-F$15 -> 0.060854197 | R24: =G24-G$15 -> -0.94203625 | S24: =H24-H$15 -> -1.1533386 | T24: =I24-I$15 -> 0.24684249 | ... V24: =K24-K$15 -> 0.64159106 | X24: =SUMPRODUCT($M24:$V24,$X$4:$AG$4) -> 0.1639567 | Y24: =SUMPRODUCT($M24:$V24,$X$5:$AG$5) -> 2.4974347 | Z24: =SUMPRODUCT($M24:$V24,$X$6:$AG$6) -> 2.3936561 | AA24: =SUMPRODUCT($M24:$V24,$X$7:$AG$7) -> 0.033041725 | AB24: =SUMPRODUCT($M24:$V24,$X$8:$AG$8) -> -0.014871917 | AC24: =SUMPRODUCT($M24:$V24,$X$9:$AG$9) -> -1.058425 | AD24: =SUMPRODUCT($M24:$V24,$X$10:$AG$10) -> -1.1093395 | AE24: =SUMPRODUCT($M24:$V24,$X$11:$AG$11) -> 0.03643189 | AF24: =SUMPRODUCT($M24:$V24,$X$12:$AG$12) -> 0.68643528 | AG24: =SUMPRODUCT($M24:$V24,$X$13:$AG$13) -> 0.47653762
A25: 8 | B25: 0.0012540824 | C25: 0.54616113 | D25: -1.2245455 | E25: -0.87999384 | F25: -0.6068162 | G25: 1.4799411 | H25: -0.36687766 | I25: -0.40923304 | J25: 0.83344716 | K25: -0.51006943 | M25: =B25-B$15 -> -0.016443116 | N25: =C25-C$15 -> 0.55219064 | O25: =D25-D$15 -> -1.2575845 | P25: =E25-E$15 -> -0.8127594 | Q25: =F25-F$15 -> -0.58960133 | R25: =G25-G$15 -> 1.5174035 | S25: =H25-H$15 -> -0.35453223 | T25: =I25-I$15 -> -0.43980648 | ... V25: =K25-K$15 -> -0.49993935 | X25: =SUMPRODUCT($M25:$V25,$X$4:$AG$4) -> -0.016367218 | Y25: =SUMPRODUCT($M25:$V25,$X$5:$AG$5) -> 0.5443417 | Z25: =SUMPRODUCT($M25:$V25,$X$6:$AG$6) -> -1.2586105 | AA25: =SUMPRODUCT($M25:$V25,$X$7:$AG$7) -> -0.78019372 | AB25: =SUMPRODUCT($M25:$V25,$X$8:$AG$8) -> -0.56602856 | AC25: =SUMPRODUCT($M25:$V25,$X$9:$AG$9) -> 1.4945227 | AD25: =SUMPRODUCT($M25:$V25,$X$10:$AG$10) -> -0.26183922 | AE25: =SUMPRODUCT($M25:$V25,$X$11:$AG$11) -> -0.52344713 | AF25: =SUMPRODUCT($M25:$V25,$X$12:$AG$12) -> 0.94159118 | AG25: =SUMPRODUCT($M25:$V25,$X$13:$AG$13) -> -0.37544326
A26: 9 | B26: -0.17451781 | C26: -0.9252292 | D26: 1.0322113 | E26: -0.24317831 | F26: 0.64296192 | G26: -0.084316859 | H26: -0.4738307 | I26: -0.16114309 | J26: -1.256032 | K26: 1.5574843 | M26: =B26-B$15 -> -0.192215 | N26: =C26-C$15 -> -0.91919969 | O26: =D26-D$15 -> 0.99917237 | P26: =E26-E$15 -> -0.17594387 | Q26: =F26-F$15 -> 0.66017679 | R26: =G26-G$15 -> -0.046854448 | S26: =H26-H$15 -> -0.46148526 | T26: =I26-I$15 -> -0.19171653 | ... V26: =K26-K$15 -> 1.5676143 | X26: =SUMPRODUCT($M26:$V26,$X$4:$AG$4) -> -0.19132778 | Y26: =SUMPRODUCT($M26:$V26,$X$5:$AG$5) -> -0.90774834 | Z26: =SUMPRODUCT($M26:$V26,$X$6:$AG$6) -> 1.0013 | AA26: =SUMPRODUCT($M26:$V26,$X$7:$AG$7) -> -0.20606694 | AB26: =SUMPRODUCT($M26:$V26,$X$8:$AG$8) -> 0.66827445 | AC26: =SUMPRODUCT($M26:$V26,$X$9:$AG$9) -> -0.00051651458 | AD26: =SUMPRODUCT($M26:$V26,$X$10:$AG$10) -> -0.53226161 | AE26: =SUMPRODUCT($M26:$V26,$X$11:$AG$11) -> -0.11090743 | AF26: =SUMPRODUCT($M26:$V26,$X$12:$AG$12) -> -1.3259287 | AG26: =SUMPRODUCT($M26:$V26,$X$13:$AG$13) -> 1.441575
A27: 10 | B27: 1.2427491 | C27: -1.2554048 | D27: 1.0855786 | E27: -0.9129 | F27: 0.026784291 | G27: 1.6927249 | H27: 1.8710602 | I27: 0.20541021 | J27: 1.0689602 | K27: 0.63146848 | M27: =B27-B$15 -> 1.2250519 | N27: =C27-C$15 -> -1.2493753 | O27: =D27-D$15 -> 1.0525397 | P27: =E27-E$15 -> -0.84566556 | Q27: =F27-F$15 -> 0.043999157 | R27: =G27-G$15 -> 1.7301874 | S27: =H27-H$15 -> 1.8834057 | T27: =I27-I$15 -> 0.17483677 | ... V27: =K27-K$15 -> 0.64159856 | X27: =SUMPRODUCT($M27:$V27,$X$4:$AG$4) -> 1.2193973 | Y27: =SUMPRODUCT($M27:$V27,$X$5:$AG$5) -> -1.2228838 | Z27: =SUMPRODUCT($M27:$V27,$X$6:$AG$6) -> 1.0579038 | AA27: =SUMPRODUCT($M27:$V27,$X$7:$AG$7) -> -0.89290084 | AB27: =SUMPRODUCT($M27:$V27,$X$8:$AG$8) -> 0.049995573 | AC27: =SUMPRODUCT($M27:$V27,$X$9:$AG$9) -> 1.7527553 | AD27: =SUMPRODUCT($M27:$V27,$X$10:$AG$10) -> 1.7832572 | AE27: =SUMPRODUCT($M27:$V27,$X$11:$AG$11) -> 0.15924351 | AF27: =SUMPRODUCT($M27:$V27,$X$12:$AG$12) -> 1.0944512 | AG27: =SUMPRODUCT($M27:$V27,$X$13:$AG$13) -> 0.59524236
A28: 11 | B28: -0.36636517 | C28: 0.63780897 | D28: 0.8268662 | E28: -0.27723605 | F28: 1.0565535 | G28: 2.2067925 | H28: -0.63085567 | I28: 0.30583377 | J28: -0.90104999 | K28: 0.1716398 | M28: =B28-B$15 -> -0.38406236 | N28: =C28-C$15 -> 0.64383847 | O28: =D28-D$15 -> 0.79382724 | P28: =E28-E$15 -> -0.21000161 | Q28: =F28-F$15 -> 1.0737683 | R28: =G28-G$15 -> 2.2442549 | S28: =H28-H$15 -> -0.61851023 | T28: =I28-I$15 -> 0.27526033 | ... V28: =K28-K$15 -> 0.18176988 | X28: =SUMPRODUCT($M28:$V28,$X$4:$AG$4) -> -0.38228961 | Y28: =SUMPRODUCT($M28:$V28,$X$5:$AG$5) -> 0.6320043 | Z28: =SUMPRODUCT($M28:$V28,$X$6:$AG$6) -> 0.79051875 | AA28: =SUMPRODUCT($M28:$V28,$X$7:$AG$7) -> -0.24138098 | AB28: =SUMPRODUCT($M28:$V28,$X$8:$AG$8) -> 1.0484892 | AC28: =SUMPRODUCT($M28:$V28,$X$9:$AG$9) -> 2.2102286 | AD28: =SUMPRODUCT($M28:$V28,$X$10:$AG$10) -> -0.59627662 | AE28: =SUMPRODUCT($M28:$V28,$X$11:$AG$11) -> 0.13297282 | AF28: =SUMPRODUCT($M28:$V28,$X$12:$AG$12) -> -0.7247005 | AG28: =SUMPRODUCT($M28:$V28,$X$13:$AG$13) -> 0.069586249
A29: 12 | B29: 0.99133786 | C29: 0.52432613 | D29: -0.57589875 | E29: -0.20999668 | F29: 1.550588 | G29: 1.2715391 | H29: 0.030732581 | I29: -1.014409 | J29: -0.49343134 | K29: -2.088819 | M29: =B29-B$15 -> 0.97364066 | N29: =C29-C$15 -> 0.53035563 | O29: =D29-D$15 -> -0.60893771 | P29: =E29-E$15 -> -0.14276224 | Q29: =F29-F$15 -> 1.5678028 | R29: =G29-G$15 -> 1.3090015 | S29: =H29-H$15 -> 0.043078015 | T29: =I29-I$15 -> -1.0449825 | ... V29: =K29-K$15 -> -2.0786889 | X29: =SUMPRODUCT($M29:$V29,$X$4:$AG$4) -> 0.96914654 | Y29: =SUMPRODUCT($M29:$V29,$X$5:$AG$5) -> 0.530091 | Z29: =SUMPRODUCT($M29:$V29,$X$6:$AG$6) -> -0.60883005 | AA29: =SUMPRODUCT($M29:$V29,$X$7:$AG$7) -> -0.13301192 | AB29: =SUMPRODUCT($M29:$V29,$X$8:$AG$8) -> 1.5127772 | AC29: =SUMPRODUCT($M29:$V29,$X$9:$AG$9) -> 1.2850952 | AD29: =SUMPRODUCT($M29:$V29,$X$10:$AG$10) -> 0.07774306 | AE29: =SUMPRODUCT($M29:$V29,$X$11:$AG$11) -> -1.1463753 | AF29: =SUMPRODUCT($M29:$V29,$X$12:$AG$12) -> -0.30429061 | AG29: =SUMPRODUCT($M29:$V29,$X$13:$AG$13) -> -2.106625
... A1017: 1000 | B1017: 0.39926353 | C1017: -0.3266436 | D1017: 2.2687587 | E1017: 0.5367822 | F1017: 1.431834 | G1017: -1.6368896 | H1017: 0.67420774 | I1017: -1.0191729 | J1017: 0.6192838 | K1017: 0.32254801 | M1017: =B1017-B$15 -> 0.38156633 | N1017: =C1017-C$15 -> -0.3206141 | O1017: =D1017-D$15 -> 2.2357198 | P1017: =E1017-E$15 -> 0.60401663 | Q1017: =F1017-F$15 -> 1.4490489 | R1017: =G1017-G$15 -> -1.5994272 | S1017: =H1017-H$15 -> 0.68655317 | T1017: =I1017-I$15 -> -1.0497463 | ... V1017: =K1017-K$15 -> 0.33267809 | X1017: =SUMPRODUCT($M1017:$V1017,$X$4:$AG$4) -> 0.3798051 | Y1017: =SUMPRODUCT($M1017:$V1017,$X$5:$AG$5) -> -0.31332189 | Z1017: =SUMPRODUCT($M1017:$V1017,$X$6:$AG$6) -> 2.2358446 | AA1017: =SUMPRODUCT($M1017:$V1017,$X$7:$AG$7) -> 0.53070759 | AB1017: =SUMPRODUCT($M1017:$V1017,$X$8:$AG$8) -> 1.3941537 | AC1017: =SUMPRODUCT($M1017:$V1017,$X$9:$AG$9) -> -1.5827092 | AD1017: =SUMPRODUCT($M1017:$V1017,$X$10:$AG$10) -> 0.57316799 | AE1017: =SUMPRODUCT($M1017:$V1017,$X$11:$AG$11) -> -1.0076144 | AF1017: =SUMPRODUCT($M1017:$V1017,$X$12:$AG$12) -> 0.62399281 | AG1017: =SUMPRODUCT($M1017:$V1017,$X$13:$AG$13) -> 0.11808569

Sheet Defaults
A1: Correlated default times
A2: Cholesky factor L of the 10 x 10 matrix with 1 on the diagonal and rho elsewhere. Each case: x = L m, with m the moment-matched numbers from the Random sheet, u = N(x), t = ln(1 - u) / ln(1 - pi) in years, default quarter = roundup(4 t); 21 means no default.
A3: L | B3: col 1 | C3: col 2 | D3: col 3 | E3: col 4 | F3: col 5 | G3: col 6 | H3: col 7 | I3: col 8 | J3: col 9 | K3: col 10
A4: Bond 1 | B4: 1 | C4: 0 | D4: 0 | E4: 0 | F4: 0 | G4: 0 | H4: 0 | I4: 0 | J4: 0 | K4: 0
A5: Bond 2 | B5: =rho/$B$4 -> 0.2 | C5: =SQRT(1-SUMSQ($B5:B5)) -> 0.9797959 | D5: 0 | E5: 0 | F5: 0 | G5: 0 | H5: 0 | I5: 0 | J5: 0 | K5: 0
A6: Bond 3 | B6: =rho/$B$4 -> 0.2 | C6: =(rho-SUMPRODUCT($B6:B6,$B5:B5))/C5 -> 0.16329932 | D6: =SQRT(1-SUMSQ($B6:C6)) -> 0.96609178 | E6: 0 | F6: 0 | G6: 0 | H6: 0 | I6: 0 | J6: 0 | K6: 0
A7: Bond 4 | B7: =rho/$B$4 -> 0.2 | C7: =(rho-SUMPRODUCT($B7:B7,$B5:B5))/C5 -> 0.16329932 | D7: =(rho-SUMPRODUCT($B7:C7,$B6:C6))/D6 -> 0.13801311 | E7: =SQRT(1-SUMSQ($B7:D7)) -> 0.95618289 | F7: 0 | G7: 0 | H7: 0 | I7: 0 | J7: 0 | K7: 0
A8: Bond 5 | B8: =rho/$B$4 -> 0.2 | C8: =(rho-SUMPRODUCT($B8:B8,$B5:B5))/C5 -> 0.16329932 | D8: =(rho-SUMPRODUCT($B8:C8,$B6:C6))/D6 -> 0.13801311 | E8: =(rho-SUMPRODUCT($B8:D8,$B7:D7))/E7 -> 0.11952286 | F8: =SQRT(1-SUMSQ($B8:E8)) -> 0.9486833 | G8: 0 | H8: 0 | I8: 0 | J8: 0 | K8: 0
A9: Bond 6 | B9: =rho/$B$4 -> 0.2 | C9: =(rho-SUMPRODUCT($B9:B9,$B5:B5))/C5 -> 0.16329932 | D9: =(rho-SUMPRODUCT($B9:C9,$B6:C6))/D6 -> 0.13801311 | E9: =(rho-SUMPRODUCT($B9:D9,$B7:D7))/E7 -> 0.11952286 | F9: =(rho-SUMPRODUCT($B9:E9,$B8:E8))/F8 -> 0.10540926 | G9: =SQRT(1-SUMSQ($B9:F9)) -> 0.94280904 | H9: 0 | I9: 0 | J9: 0 | K9: 0
