Workbook

Sheet 1 Amortization
A1: Questions (a) and (b): Amortization schedules and charts
A2: Mini-Project 'The Two-Loan Comparison' (textbook pp. 36-37). A borrower needs $5,000 for 2 years with monthly payments. Chase Bank: 10% simple annual rate, no fees. Wells Fargo Bank: 7% simple annual rate with a 2% origination fee that is financed into the loan.
A3: Colour code: blue = given input, black = formula, green = link from another sheet. Dollar amounts to the cent; annual rates to the basis point (0.00%); monthly rates shown with one more decimal. Check cells are rounded to 8 decimals so that computer floating-point noise shows as $0.00.
A5: Given inputs
B6: Chase Bank | C6: Wells Fargo Bank | D6: Note
A7: Cash the borrower receives ($) | B7: 5000 | C7: 5000 | D7: Given: the borrower needs $5,000 from either bank.
A8: Simple annual interest rate | B8: 0.1 | C8: 0.07 | D8: Given. 'Simple annual' means the monthly rate is the annual rate divided by 12, with no compounding adjustment.
A9: Payments per year | B9: 12 | C9: 12 | D9: Given: monthly payments, made at the end of each month.
A10: Term (years) | B10: 2 | C10: 2 | D10: Given.
A11: Origination fee (% of the loan) | B11: 0 | C11: 0.02 | D11: Given. Wells Fargo's fee is financed: it is added to the balance owed instead of being paid in cash.
A13: Step 1: Convert the loan terms to monthly units
B14: Chase Bank | C14: Wells Fargo Bank | D14: Formula and meaning
A15: Monthly interest rate r = annual rate / payments per year | B15: =B8/B9 -> 0.0083333333 | C15: =C8/C9 -> 0.0058333333 | D15: 10% / 12 = 0.8333% per month; 7% / 12 = 0.5833% per month. This is the rate charged on the balance each month.
A16: Number of monthly payments n = years x payments per year | B16: =B10*B9 -> 24 | C16: =C10*C9 -> 24 | D16: 2 x 12 = 24 payments.
A18: Step 2: Amount owed at the start (V0)
B19: Chase Bank | C19: Wells Fargo Bank | D19: Formula and meaning
A20: Origination fee ($) = cash received x fee % | B20: =B7*B11 -> 0 | C20: =C7*C11 -> 100 | D20: Wells Fargo: 2% x $5,000 = $100.
A21: Amount owed at the start V0 ($) = cash received + fee | B21: =B7+B20 -> 5000 | C21: =C7+C20 -> 5100 | D21: The balance the payments must repay. Wells Fargo's borrower receives $5,000 but owes $5,100 from day one.
A23: Step 3: Monthly payment C. Flat annuity (textbook Section 2.5): V0 = (C / r) x (1 - d^n) with d = 1/(1+r), so C = V0 / [(1 - (1+r)^-n) / r]
B24: Chase Bank | C24: Wells Fargo Bank | D24: Formula and meaning
A25: n-month discount factor d^n = (1 + r)^-n | B25: =(1+B15)^-B16 -> 0.81940954 | C25: =(1+C15)^-C16 -> 0.86971192 | D25: Present value of $1 paid at month 24.
A26: Annuity factor = (1 - d^n) / r | B26: =(1-B25)/B15 -> 21.670855 | C26: =(1-C25)/C15 -> 22.335099 | D26: Present value of $1 paid at the end of each month for 24 months.
A27: Monthly payment C ($) = V0 / annuity factor | B27: =B21/B26 -> 230.72463 | C27: =C21/C26 -> 228.34015 | D27: The level payment whose present value at the loan's own rate equals V0.
A28: Check with Excel: =PMT(r, n, -V0) ($) | B28: =PMT(B15,B16,-B21) -> 230.72463 | C28: =PMT(C15,C16,-C21) -> 228.34015 | D28: PMT(rate, nper, pv). pv is entered as -V0 (the amount received, opposite sign to the payments) so the result is the positive payment. fv and type are omitted: balance 0 after the last payment, payments at the end of each month.
A29: Difference between the two (should be $0.00) | B29: =ROUND(B27-B28,8) -> 0 | C29: =ROUND(C27-C28,8) -> 0
A31: Question (a): Amortization tables (one row per monthly payment)
A32: Each row: interest = beginning balance x r; principal reduction = payment - interest; ending balance = beginning balance - principal reduction. In month 24 the payment is set to the remaining balance plus its interest so the loan closes at exactly $0.00 (it equals C to the cent; the check row confirms this). The 'Borrower cash flow' column (+cash received at month 0, -payment each month) is used for the APR in Step 4.
B33: Chase Bank | J33: Wells Fargo Bank
B34: Period i (month) | C34: Beginning balance V(i) ($) | D34: Interest r x V(i) ($) | E34: Payment C ($) | F34: Principal reduction C - r x V(i) ($) | G34: Ending balance V(i+1) ($) | H34: Borrower cash flow ($) | J34: Period i (month) | K34: Beginning balance V(i) ($) | L34: Interest r x V(i) ($) | M34: Payment C ($) | N34: Principal reduction C - r x V(i) ($) | O34: Ending balance V(i+1) ($) | P34: Borrower cash flow ($)
B35: 0 | G35: =$B$21 -> 5000 | H35: =$B$7 -> 5000 | J35: 0 | O35: =$C$21 -> 5100 | P35: =$C$7 -> 5000
B36: =B35+1 -> 1 | C36: =G35 -> 5000 | D36: =C36*$B$15 -> 41.666667 | E36: =IF(B36<$B$16,$B$27,C36+D36) -> 230.72463 | F36: =E36-D36 -> 189.05797 | G36: =C36-F36 -> 4810.942 | H36: =-E36 -> -230.72463 | J36: =J35+1 -> 1 | K36: =O35 -> 5100 | L36: =K36*$C$15 -> 29.75 | M36: =IF(J36<$C$16,$C$27,K36+L36) -> 228.34015 | N36: =M36-L36 -> 198.59015 | O36: =K36-N36 -> 4901.4098 | P36: =-M36 -> -228.34015
B37: =B36+1 -> 2 | C37: =G36 -> 4810.942 | D37: =C37*$B$15 -> 40.091184 | E37: =IF(B37<$B$16,$B$27,C37+D37) -> 230.72463 | F37: =E37-D37 -> 190.63345 | G37: =C37-F37 -> 4620.3086 | H37: =-E37 -> -230.72463 | J37: =J36+1 -> 2 | K37: =O36 -> 4901.4098 | L37: =K37*$C$15 -> 28.591557 | M37: =IF(J37<$C$16,$C$27,K37+L37) -> 228.34015 | N37: =M37-L37 -> 199.7486 | O37: =K37-N37 -> 4701.6613 | P37: =-M37 -> -228.34015
B38: =B37+1 -> 3 | C38: =G37 -> 4620.3086 | D38: =C38*$B$15 -> 38.502572 | E38: =IF(B38<$B$16,$B$27,C38+D38) -> 230.72463 | F38: =E38-D38 -> 192.22206 | G38: =C38-F38 -> 4428.0865 | H38: =-E38 -> -230.72463 | J38: =J37+1 -> 3 | K38: =O37 -> 4701.6613 | L38: =K38*$C$15 -> 27.426357 | M38: =IF(J38<$C$16,$C$27,K38+L38) -> 228.34015 | N38: =M38-L38 -> 200.9138 | O38: =K38-N38 -> 4500.7475 | P38: =-M38 -> -228.34015
B39: =B38+1 -> 4 | C39: =G38 -> 4428.0865 | D39: =C39*$B$15 -> 36.900721 | E39: =IF(B39<$B$16,$B$27,C39+D39) -> 230.72463 | F39: =E39-D39 -> 193.82391 | G39: =C39-F39 -> 4234.2626 | H39: =-E39 -> -230.72463 | J39: =J38+1 -> 4 | K39: =O38 -> 4500.7475 | L39: =K39*$C$15 -> 26.25436 | M39: =IF(J39<$C$16,$C$27,K39+L39) -> 228.34015 | N39: =M39-L39 -> 202.08579 | O39: =K39-N39 -> 4298.6617 | P39: =-M39 -> -228.34015
B40: =B39+1 -> 5 | C40: =G39 -> 4234.2626 | D40: =C40*$B$15 -> 35.285522 | E40: =IF(B40<$B$16,$B$27,C40+D40) -> 230.72463 | F40: =E40-D40 -> 195.43911 | G40: =C40-F40 -> 4038.8235 | H40: =-E40 -> -230.72463 | J40: =J39+1 -> 5 | K40: =O39 -> 4298.6617 | L40: =K40*$C$15 -> 25.075526 | M40: =IF(J40<$C$16,$C$27,K40+L40) -> 228.34015 | N40: =M40-L40 -> 203.26463 | O40: =K40-N40 -> 4095.397 | P40: =-M40 -> -228.34015
B41: =B40+1 -> 6 | C41: =G40 -> 4038.8235 | D41: =C41*$B$15 -> 33.656863 | E41: =IF(B41<$B$16,$B$27,C41+D41) -> 230.72463 | F41: =E41-D41 -> 197.06777 | G41: =C41-F41 -> 3841.7557 | H41: =-E41 -> -230.72463 | J41: =J40+1 -> 6 | K41: =O40 -> 4095.397 | L41: =K41*$C$15 -> 23.889816 | M41: =IF(J41<$C$16,$C$27,K41+L41) -> 228.34015 | N41: =M41-L41 -> 204.45034 | O41: =K41-N41 -> 3890.9467 | P41: =-M41 -> -228.34015
B42: =B41+1 -> 7 | C42: =G41 -> 3841.7557 | D42: =C42*$B$15 -> 32.014631 | E42: =IF(B42<$B$16,$B$27,C42+D42) -> 230.72463 | F42: =E42-D42 -> 198.71 | G42: =C42-F42 -> 3643.0457 | H42: =-E42 -> -230.72463 | J42: =J41+1 -> 7 | K42: =O41 -> 3890.9467 | L42: =K42*$C$15 -> 22.697189 | M42: =IF(J42<$C$16,$C$27,K42+L42) -> 228.34015 | N42: =M42-L42 -> 205.64296 | O42: =K42-N42 -> 3685.3037 | P42: =-M42 -> -228.34015
B43: =B42+1 -> 8 | C43: =G42 -> 3643.0457 | D43: =C43*$B$15 -> 30.358714 | E43: =IF(B43<$B$16,$B$27,C43+D43) -> 230.72463 | F43: =E43-D43 -> 200.36592 | G43: =C43-F43 -> 3442.6798 | H43: =-E43 -> -230.72463 | J43: =J42+1 -> 8 | K43: =O42 -> 3685.3037 | L43: =K43*$C$15 -> 21.497605 | M43: =IF(J43<$C$16,$C$27,K43+L43) -> 228.34015 | N43: =M43-L43 -> 206.84255 | O43: =K43-N43 -> 3478.4612 | P43: =-M43 -> -228.34015
B44: =B43+1 -> 9 | C44: =G43 -> 3442.6798 | D44: =C44*$B$15 -> 28.688998 | E44: =IF(B44<$B$16,$B$27,C44+D44) -> 230.72463 | F44: =E44-D44 -> 202.03563 | G44: =C44-F44 -> 3240.6442 | H44: =-E44 -> -230.72463 | J44: =J43+1 -> 9 | K44: =O43 -> 3478.4612 | L44: =K44*$C$15 -> 20.291024 | M44: =IF(J44<$C$16,$C$27,K44+L44) -> 228.34015 | N44: =M44-L44 -> 208.04913 | O44: =K44-N44 -> 3270.4121 | P44: =-M44 -> -228.34015
B45: =B44+1 -> 10 | C45: =G44 -> 3240.6442 | D45: =C45*$B$15 -> 27.005368 | E45: =IF(B45<$B$16,$B$27,C45+D45) -> 230.72463 | F45: =E45-D45 -> 203.71926 | G45: =C45-F45 -> 3036.9249 | H45: =-E45 -> -230.72463 | J45: =J44+1 -> 10 | K45: =O44 -> 3270.4121 | L45: =K45*$C$15 -> 19.077404 | M45: =IF(J45<$C$16,$C$27,K45+L45) -> 228.34015 | N45: =M45-L45 -> 209.26275 | O45: =K45-N45 -> 3061.1493 | P45: =-M45 -> -228.34015
...

Sheet 2 Payoff Analysis
A1: Question (c): Payoff analysis
A2: For each early payoff month m = 1 to 24: (1) the payoff balance, the amount still owed right after the m-th scheduled payment, and (2) the present value at month m of the payments not yet made (months m+1 to 24), discounted at the Chase loan rate. Then compare the two.
A3: Colour code: blue = given input, black = formula, green = link from another sheet. Dollar amounts to the cent; annual rates to the basis point (0.00%); monthly rates shown with one more decimal. Check cells are rounded to 8 decimals so that computer floating-point noise shows as $0.00.
A5: Given inputs (linked from Sheet 1)
B6: Value | C6: Note
A7: Chase simple annual rate | B7: ='1 Amortization'!B8 -> 0.1 | C7: Given: the assignment says to discount the remaining payments at the Chase loan rate, for both loans.
A8: Monthly discount rate = Chase annual rate / 12 | B8: ='1 Amortization'!B15 -> 0.0083333333
A9: Number of payments n | B9: ='1 Amortization'!B16 -> 24
A10: Chase monthly payment C ($) | B10: ='1 Amortization'!B27 -> 230.72463
A11: Wells Fargo monthly payment C ($) | B11: ='1 Amortization'!C27 -> 228.34015
A13: Equations
A14: Payoff balance at month m = V(m), the ending balance after payment m in the Sheet 1 amortization table.
A15: PV of remaining payments at month m = C x [1 - (1 + r_Chase)^-(n - m)] / r_Chase: a flat annuity of n - m payments, the first due one month after m (textbook Section 2.5). In Excel: PV(r_Chase, n - m, -C); pmt is entered as -C so the present value is positive; fv and type omitted (0, end of period).
C17: Chase Bank | F17: Wells Fargo Bank
A18: Payoff month m (after the m-th payment) | B18: Remaining payments n - m | C18: Payoff balance V(m) ($) | D18: PV of remaining payments at Chase's rate ($) | E18: Balance - PV ($) | F18: Payoff balance V(m) ($) | G18: PV of remaining payments at Chase's rate ($) | H18: Balance - PV ($)
A19: 1 | B19: =$B$9-A19 -> 23 | C19: ='1 Amortization'!G36 -> 4810.942 | D19: =PV($B$8,B19,-$B$10) -> 4810.942 | E19: =ROUND(C19-D19,8) -> 0 | F19: ='1 Amortization'!O36 -> 4901.4098 | G19: =PV($B$8,B19,-$B$11) -> 4761.2222 | H19: =ROUND(F19-G19,8) -> 140.18763
A20: =A19+1 -> 2 | B20: =$B$9-A20 -> 22 | C20: ='1 Amortization'!G37 -> 4620.3086 | D20: =PV($B$8,B20,-$B$10) -> 4620.3086 | E20: =ROUND(C20-D20,8) -> 0 | F20: ='1 Amortization'!O37 -> 4701.6613 | G20: =PV($B$8,B20,-$B$11) -> 4572.5589 | H20: =ROUND(F20-G20,8) -> 129.10234
A21: =A20+1 -> 3 | B21: =$B$9-A21 -> 21 | C21: ='1 Amortization'!G38 -> 4428.0865 | D21: =PV($B$8,B21,-$B$10) -> 4428.0865 | E21: =ROUND(C21-D21,8) -> 0 | F21: ='1 Amortization'!O38 -> 4500.7475 | G21: =PV($B$8,B21,-$B$11) -> 4382.3234 | H21: =ROUND(F21-G21,8) -> 118.42403
A22: =A21+1 -> 4 | B22: =$B$9-A22 -> 20 | C22: ='1 Amortization'!G39 -> 4234.2626 | D22: =PV($B$8,B22,-$B$10) -> 4234.2626 | E22: =ROUND(C22-D22,8) -> 0 | F22: ='1 Amortization'!O39 -> 4298.6617 | G22: =PV($B$8,B22,-$B$11) -> 4190.5026 | H22: =ROUND(F22-G22,8) -> 108.15903
A23: =A22+1 -> 5 | B23: =$B$9-A23 -> 19 | C23: ='1 Amortization'!G40 -> 4038.8235 | D23: =PV($B$8,B23,-$B$10) -> 4038.8235 | E23: =ROUND(C23-D23,8) -> 0 | F23: ='1 Amortization'!O40 -> 4095.397 | G23: =PV($B$8,B23,-$B$11) -> 3997.0833 | H23: =ROUND(F23-G23,8) -> 98.313704
A24: =A23+1 -> 6 | B24: =$B$9-A24 -> 18 | C24: ='1 Amortization'!G41 -> 3841.7557 | D24: =PV($B$8,B24,-$B$10) -> 3841.7557 | E24: =ROUND(C24-D24,8) -> 0 | F24: ='1 Amortization'!O41 -> 3890.9467 | G24: =PV($B$8,B24,-$B$11) -> 3802.0522 | H24: =ROUND(F24-G24,8) -> 88.894493
A25: =A24+1 -> 7 | B25: =$B$9-A25 -> 17 | C25: ='1 Amortization'!G42 -> 3643.0457 | D25: =PV($B$8,B25,-$B$10) -> 3643.0457 | E25: =ROUND(C25-D25,8) -> 0 | F25: ='1 Amortization'!O42 -> 3685.3037 | G25: =PV($B$8,B25,-$B$11) -> 3605.3958 | H25: =ROUND(F25-G25,8) -> 79.907913
A26: =A25+1 -> 8 | B26: =$B$9-A26 -> 16 | C26: ='1 Amortization'!G43 -> 3442.6798 | D26: =PV($B$8,B26,-$B$10) -> 3442.6798 | E26: =ROUND(C26-D26,8) -> 0 | F26: ='1 Amortization'!O43 -> 3478.4612 | G26: =PV($B$8,B26,-$B$11) -> 3407.1006 | H26: =ROUND(F26-G26,8) -> 71.360553
A27: =A26+1 -> 9 | B27: =$B$9-A27 -> 15 | C27: ='1 Amortization'!G44 -> 3240.6442 | D27: =PV($B$8,B27,-$B$10) -> 3240.6442 | E27: =ROUND(C27-D27,8) -> 0 | F27: ='1 Amortization'!O44 -> 3270.4121 | G27: =PV($B$8,B27,-$B$11) -> 3207.153 | H27: =ROUND(F27-G27,8) -> 63.259072
A28: =A27+1 -> 10 | B28: =$B$9-A28 -> 14 | C28: ='1 Amortization'!G45 -> 3036.9249 | D28: =PV($B$8,B28,-$B$10) -> 3036.9249 | E28: =ROUND(C28-D28,8) -> 0 | F28: ='1 Amortization'!O45 -> 3061.1493 | G28: =PV($B$8,B28,-$B$11) -> 3005.5391 | H28: =ROUND(F28-G28,8) -> 55.6102
A29: =A28+1 -> 11 | B29: =$B$9-A29 -> 13 | C29: ='1 Amortization'!G46 -> 2831.508 | D29: =PV($B$8,B29,-$B$10) -> 2831.508 | E29: =ROUND(C29-D29,8) -> 0 | F29: ='1 Amortization'!O46 -> 2850.6659 | G29: =PV($B$8,B29,-$B$11) -> 2802.2451 | H29: =ROUND(F29-G29,8) -> 48.420745
A30: =A29+1 -> 12 | B30: =$B$9-A30 -> 12 | C30: ='1 Amortization'!G47 -> 2624.3793 | D30: =PV($B$8,B30,-$B$10) -> 2624.3793 | E30: =ROUND(C30-D30,8) -> 0 | F30: ='1 Amortization'!O47 -> 2638.9546 | G30: =PV($B$8,B30,-$B$11) -> 2597.257 | H30: =ROUND(F30-G30,8) -> 41.697587
A31: =A30+1 -> 13 | B31: =$B$9-A31 -> 11 | C31: ='1 Amortization'!G48 -> 2415.5245 | D31: =PV($B$8,B31,-$B$10) -> 2415.5245 | E31: =ROUND(C31-D31,8) -> 0 | F31: ='1 Amortization'!O48 -> 2426.0083 | G31: =PV($B$8,B31,-$B$11) -> 2390.5607 | H31: =ROUND(F31-G31,8) -> 35.44768
... A42: =A41+1 -> 24 | B42: =$B$9-A42 -> 0 | C42: ='1 Amortization'!G59 -> 0 | D42: =PV($B$8,B42,-$B$10) -> 0 | E42: =ROUND(C42-D42,8) -> 0 | F42: ='1 Amortization'!O59 -> 0 | G42: =PV($B$8,B42,-$B$11) -> 0 | H42: =ROUND(F42-G42,8) -> 0
A44: Checks
B45: Value | C45: Note
A46: Chase: largest |balance - PV| over all months (should be $0.00) | B46: =MAX(MAX(E19:E42),-MIN(E19:E42)) -> 0 | C46: For Chase the two columns agree in every month: a loan balance is the PV of its remaining payments at the loan's own rate (textbook 2.5.4).
A47: Wells Fargo: balance - PV after the first payment, m = 1 ($) | B47: =H19 -> 140.18763 | C47: Largest gap in the table; it shrinks to $0.00 at month 24.
A48: Wells Fargo, m = 12, PV by the explicit formula C x [1 - (1+r)^-(n-m)] / r ($) | B48: =$B$11*(1-(1+$B$8)^-(B30))/$B$8 -> 2597.257 | C48: Same number as the PV function in the table (next row), so the function is being used correctly.
A49: Difference from the PV function value in the table (should be $0.00) | B49: =ROUND(B48-G30,8) -> 0
A51: What the relationship between payoff balance and PV of remaining payments tells you
A52: 1. Chase: payoff balance = PV of remaining payments in every month. The balance is, by definition, the present value of the payments still owed, discounted at the loan's own contract rate; the discount rate here is that same 10% rate, so the two agree. Paying Chase off early is a fair trade: the cash handed over equals the value of the debt removed.
A53: 2. Wells Fargo: the payoff balance is above the PV of the remaining payments in every month before the last ($140.19 after month 1, falling to $0.00 at month 24). The payments were set using a 7% rate, but at a 10% discount rate they are worth less. The gap is the value of Wells Fargo's below-market rate.
A54: 3. Decision rule: a borrower whose alternative cost of money is 10% should not prepay the Wells Fargo loan or refinance it with Chase. Paying the balance removes a debt that is worth less than the balance, so the borrower gives the rate advantage back to the bank. Prepaying only pays when the alternative rate is below the contract rate; then the PV exceeds the balance and the gap changes sign.
A55: 4. Price and value: the same contract is worth different amounts to the two sides because each discounts at its own rate. To a borrower whose money costs 10%, the 7% loan is worth less than its balance. To Wells Fargo, whose money costs 2%, the promised payments alone would be worth more than the balance; once expected defaults and prepayments are included (Sheet 3), the 1,000-loan portfolio is worth $5,050,489.52: below the $5,100,000 booked but above the $5,000,000 lent. The borrower's loss from prepaying and the bank's gain are not equal amounts, because the discount rates and the default assumption differ.

Sheet 3 Bank View
A1: Question (d): The bank's view. Wells Fargo's expected cash flows on 1,000 identical loans
A2: Wells Fargo funds the loans at 2%/year, borrowers default at 6%/year with no recovery, and borrowers prepay 1% of the balance per month. The sheet projects the expected monthly principal and interest on 1,000 identical Wells Fargo loans, discounts them at the funding cost, and then repeats the valuation for contract rates of 5% to 12% and fees of 0% to 4% in a two-way data table.
A3: Colour code: blue = given input, black = formula, green = link from another sheet. Dollar amounts to the cent; annual rates to the basis point (0.00%); monthly rates shown with one more decimal. Check cells are rounded to 8 decimals so that computer floating-point noise shows as $0.00.
A5: Given inputs
B6: Value | C6: Per month | D6: Note
A7: Number of loans in the portfolio | B7: 1000 | D7: Given.
A8: Cash lent per loan ($) | B8: ='1 Amortization'!C7 -> 5000 | D8: The borrower's $5,000, linked from Sheet 1.
A9: Contract rate, simple annual | B9: 0.07 | C9: =B9/12 -> 0.0058333333 | D9: Wells Fargo's 7%, typed as a value because Question (d)(ii) varies it in the data table below (Excel needs a plain input cell). Row 17 checks it matches Sheet 1.
A10: Origination fee (% of the loan) | B10: 0.02 | D10: Wells Fargo's 2%, typed for the same reason. Financed: the bank pays out $5,000 but books $5,100 per loan.
A11: Term (months) | B11: ='1 Amortization'!C16 -> 24
A12: Funding cost, annual | B12: 0.02 | C12: =B12/12 -> 0.0016666667 | D12: Given: 2%/year = 0.167%/month. The bank's cost of money, used as the discount rate for its cash flows.
A13: Default rate, annual | B13: 0.06 | C13: =B13/12 -> 0.005 | D13: Given: 6%/year = 0.50% of the loans outstanding default each month.
A14: Recovery on a defaulted balance | B14: 0 | D14: Given: recovering nothing.
A15: Prepayment rate, per month | B15: 0.01 | D15: Given: 1% of the remaining balance is repaid early each month, in addition to the scheduled principal.
A17: Check: contract rate and fee equal the Wells Fargo terms on Sheet 1 (both TRUE) | B17: =B9='1 Amortization'!C8 -> TRUE | C17: =B10='1 Amortization'!C11 -> TRUE
A19: Step 1: Per-loan terms at the inputs above
B20: Value | C20: Formula and meaning
A21: Amount booked per loan V0 ($) = cash lent x (1 + fee) | B21: =B8*(1+B10) -> 5100 | C21: $5,000 x 1.02 = $5,100.
A22: Monthly payment per loan C ($) = r x V0 / [1 - (1 + r)^-n] | B22: =B21*C9/(1-(1+C9)^-B11) -> 228.34015 | C22: Same annuity formula as Sheet 1, Step 3, using the monthly contract rate in C9.
A23: Check: C - Wells Fargo payment on Sheet 1 (should be $0.00 while the inputs match) | B23: =ROUND(B22-'1 Amortization'!C27,8) -> 0
A24: Monthly survival factor = (1 - monthly default rate) x (1 - prepayment rate) | B24: =(1-C13)*(1-B15) -> 0.98505 | C24: Share of this month's loans that are still on the books next month: 0.995 x 0.99 = 98.505%.
A26: Assumptions about timing and probabilities (the assignment gives the rates but not the order of events)
A27: 1. Order within each month: (i) 0.50% of the loans outstanding at the start of the month default; they make no payment that month and nothing is recovered. (ii) The remaining loans make the scheduled payment, split into interest and principal exactly as in the per-loan schedule. (iii) 1% of the balance left after the scheduled payment is prepaid.
A28: 2. Rates are applied to the pool as expected values: 0.50% of 1,000 loans is 5 loans defaulting in month 1, so loan counts are fractional averages, not whole loans.
A29: 3. Prepayment treatment used here: each month 1% of the balance remaining after the scheduled payment is repaid early, modelled as 1% of the loans repaying in full. Surviving loans keep their original 24-month schedule, so the pool's scheduled payments scale down with the surviving fraction. The assignment's wording (borrowers 'making extra principal payments') can also be read as every borrower paying the fixed $228.34 plus 1% of the remaining balance each month; then each loan pays off in month 22 and, with the same default timing and discount rate, the NPV is $53,409.38 instead of $50,489.52. The two readings differ only in when the principal arrives; this workbook uses the first.
A30: 4. Cash at time 0: the bank pays out $5,000 per loan. The $100 fee is financed, so no cash is received up front; it is collected through the payments on the $5,100 booked.
A31: 5. Discounting: expected monthly collections are discounted at the funding cost, as the assignment specifies. No separate risk premium is charged; default risk enters only through the expected losses.
A32: Question (d)(i): Projected monthly principal and interest, aggregated over the 1,000 loans
B33: Per loan (recursive schedule at the inputs above; month-24 principal set to the remaining balance so it closes at $0.00) | F33: Portfolio: expected values ($ unless stated)
A34: Month t | B34: Beginning balance per loan ($) | C34: Interest per loan ($) = r x beginning balance | D34: Scheduled principal per loan ($) = C - interest | E34: Ending balance per loan ($) | F34: Loans on the books at the start of the month (expected) | G34: Pool balance at start ($) = loans x beginning balance | H34: Balance written off ($) = monthly default rate x pool balance | I34: Recoveries ($) = recovery rate x written off | J34: Interest collected ($) = (1 - default rate) x loans x interest per loan | K34: Scheduled principal collected ($) = (1 - default rate) x loans x scheduled principal | L34: Prepaid principal ($) = prepayment rate x (1 - default rate) x loans x ending balance per loan | M34: Total principal collected ($) = scheduled + prepaid | N34: Total cash collected ($) = recoveries + interest + principal | O34: Pool balance at end ($) = start - written off - principal collected | P34: Discount factor = 1 / (1 + monthly funding cost)^t | Q34: PV of cash collected ($) = cash x discount factor
A35: 1 | B35: =$B$21 -> 5100 | C35: =B35*$C$9 -> 29.75 | D35: =IF(A35<$B$11,$B$22-C35,B35) -> 198.59015 | E35: =B35-D35 -> 4901.4098 | F35: =$B$7 -> 1000 | G35: =F35*B35 -> 5100000 | H35: =$C$13*G35 -> 25500 | I35: =$B$14*H35 -> 0 | J35: =(1-$C$13)*F35*C35 -> 29601.25 | K35: =(1-$C$13)*F35*D35 -> 197597.2 | L35: =$B$15*(1-$C$13)*F35*E35 -> 48769.028 | M35: =K35+L35 -> 246366.23 | N35: =I35+J35+M35 -> 275967.48 | O35: =G35-H35-M35 -> 4828133.8 | P35: =1/(1+$C$12)^A35 -> 0.99833611 | Q35: =N35*P35 -> 275508.3
A36: =A35+1 -> 2 | B36: =E35 -> 4901.4098 | C36: =B36*$C$9 -> 28.591557 | D36: =IF(A36<$B$11,$B$22-C36,B36) -> 199.7486 | E36: =B36-D36 -> 4701.6613 | F36: =F35*$B$24 -> 985.05 | G36: =F36*B36 -> 4828133.8 | H36: =$C$13*G36 -> 24140.669 | I36: =$B$14*H36 -> 0 | J36: =(1-$C$13)*F36*C36 -> 28023.293 | K36: =(1-$C$13)*F36*D36 -> 195778.54 | L36: =$B$15*(1-$C$13)*F36*E36 -> 46082.146 | M36: =K36+L36 -> 241860.69 | N36: =I36+J36+M36 -> 269883.98 | O36: =G36-H36-M36 -> 4562132.4 | P36: =1/(1+$C$12)^A36 -> 0.99667498 | Q36: =N36*P36 -> 268986.61
A37: =A36+1 -> 3 | B37: =E36 -> 4701.6613 | C37: =B37*$C$9 -> 27.426357 | D37: =IF(A37<$B$11,$B$22-C37,B37) -> 200.9138 | E37: =B37-D37 -> 4500.7475 | F37: =F36*$B$24 -> 970.3235 | G37: =F37*B37 -> 4562132.4 | H37: =$C$13*G37 -> 22810.662 | I37: =$B$14*H37 -> 0 | J37: =(1-$C$13)*F37*C37 -> 26479.377 | K37: =(1-$C$13)*F37*D37 -> 193976.62 | L37: =$B$15*(1-$C$13)*F37*E37 -> 43453.451 | M37: =K37+L37 -> 237430.07 | N37: =I37+J37+M37 -> 263909.45 | O37: =G37-H37-M37 -> 4301891.7 | P37: =1/(1+$C$12)^A37 -> 0.99501662 | Q37: =N37*P37 -> 262594.29
A38: =A37+1 -> 4 | B38: =E37 -> 4500.7475 | C38: =B38*$C$9 -> 26.25436 | D38: =IF(A38<$B$11,$B$22-C38,B38) -> 202.08579 | E38: =B38-D38 -> 4298.6617 | F38: =F37*$B$24 -> 955.81717 | G38: =F38*B38 -> 4301891.7 | H38: =$C$13*G38 -> 21509.458 | I38: =$B$14*H38 -> 0 | J38: =(1-$C$13)*F38*C38 -> 24968.896 | K38: =(1-$C$13)*F38*D38 -> 192191.28 | L38: =$B$15*(1-$C$13)*F38*E38 -> 40881.909 | M38: =K38+L38 -> 233073.19 | N38: =I38+J38+M38 -> 258042.09 | O38: =G38-H38-M38 -> 4047309 | P38: =1/(1+$C$12)^A38 -> 0.99336102 | Q38: =N38*P38 -> 256328.95
A39: =A38+1 -> 5 | B39: =E38 -> 4298.6617 | C39: =B39*$C$9 -> 25.075526 | D39: =IF(A39<$B$11,$B$22-C39,B39) -> 203.26463 | E39: =B39-D39 -> 4095.397 | F39: =F38*$B$24 -> 941.5277 | G39: =F39*B39 -> 4047309 | H39: =$C$13*G39 -> 20236.545 | I39: =$B$14*H39 -> 0 | J39: =(1-$C$13)*F39*C39 -> 23491.256 | K39: =(1-$C$13)*F39*D39 -> 190422.38 | L39: =$B$15*(1-$C$13)*F39*E39 -> 38366.501 | M39: =K39+L39 -> 228788.88 | N39: =I39+J39+M39 -> 252280.14 | O39: =G39-H39-M39 -> 3798283.6 | P39: =1/(1+$C$12)^A39 -> 0.99170817 | Q39: =N39*P39 -> 250188.27
A40: =A39+1 -> 6 | B40: =E39 -> 4095.397 | C40: =B40*$C$9 -> 23.889816 | D40: =IF(A40<$B$11,$B$22-C40,B40) -> 204.45034 | E40: =B40-D40 -> 3890.9467 | F40: =F39*$B$24 -> 927.45186 | G40: =F40*B40 -> 3798283.6 | H40: =$C$13*G40 -> 18991.418 | I40: =$B$14*H40 -> 0 | J40: =(1-$C$13)*F40*C40 -> 22045.871 | K40: =(1-$C$13)*F40*D40 -> 188669.76 | L40: =$B$15*(1-$C$13)*F40*E40 -> 35906.224 | M40: =K40+L40 -> 224575.98 | N40: =I40+J40+M40 -> 246621.85 | O40: =G40-H40-M40 -> 3554716.2 | P40: =1/(1+$C$12)^A40 -> 0.99005808 | Q40: =N40*P40 -> 244169.96
A41: =A40+1 -> 7 | B41: =E40 -> 3890.9467 | C41: =B41*$C$9 -> 22.697189 | D41: =IF(A41<$B$11,$B$22-C41,B41) -> 205.64296 | E41: =B41-D41 -> 3685.3037 | F41: =F40*$B$24 -> 913.58646 | G41: =F41*B41 -> 3554716.2 | H41: =$C$13*G41 -> 17773.581 | I41: =$B$14*H41 -> 0 | J41: =(1-$C$13)*F41*C41 -> 20632.165 | K41: =(1-$C$13)*F41*D41 -> 186933.26 | L41: =$B$15*(1-$C$13)*F41*E41 -> 33500.094 | M41: =K41+L41 -> 220433.36 | N41: =I41+J41+M41 -> 241065.52 | O41: =G41-H41-M41 -> 3316509.3 | P41: =1/(1+$C$12)^A41 -> 0.98841072 | Q41: =N41*P41 -> 238271.75
A42: =A41+1 -> 8 | B42: =E41 -> 3685.3037 | C42: =B42*$C$9 -> 21.497605 | D42: =IF(A42<$B$11,$B$22-C42,B42) -> 206.84255 | E42: =B42-D42 -> 3478.4612 | F42: =F41*$B$24 -> 899.92834 | G42: =F42*B42 -> 3316509.3 | H42: =$C$13*G42 -> 16582.546 | I42: =$B$14*H42 -> 0 | J42: =(1-$C$13)*F42*C42 -> 19249.573 | K42: =(1-$C$13)*F42*D42 -> 185212.75 | L42: =$B$15*(1-$C$13)*F42*E42 -> 31147.14 | M42: =K42+L42 -> 216359.89 | N42: =I42+J42+M42 -> 235609.47 | O42: =G42-H42-M42 -> 3083566.8 | P42: =1/(1+$C$12)^A42 -> 0.98676611 | Q42: =N42*P42 -> 232491.44
A43: =A42+1 -> 9 | B43: =E42 -> 3478.4612 | C43: =B43*$C$9 -> 20.291024 | D43: =IF(A43<$B$11,$B$22-C43,B43) -> 208.04913 | E43: =B43-D43 -> 3270.4121 | F43: =F42*$B$24 -> 886.47441 | G43: =F43*B43 -> 3083566.8 | H43: =$C$13*G43 -> 15417.834 | I43: =$B$14*H43 -> 0 | J43: =(1-$C$13)*F43*C43 -> 17897.536 | K43: =(1-$C$13)*F43*D43 -> 183508.08 | L43: =$B$15*(1-$C$13)*F43*E43 -> 28846.409 | M43: =K43+L43 -> 212354.49 | N43: =I43+J43+M43 -> 230252.02 | O43: =G43-H43-M43 -> 2855794.5 | P43: =1/(1+$C$12)^A43 -> 0.98512424 | Q43: =N43*P43 -> 226826.85
A44: =A43+1 -> 10 | B44: =E43 -> 3270.4121 | C44: =B44*$C$9 -> 19.077404 | D44: =IF(A44<$B$11,$B$22-C44,B44) -> 209.26275 | E44: =B44-D44 -> 3061.1493 | F44: =F43*$B$24 -> 873.22162 | G44: =F44*B44 -> 2855794.5 | H44: =$C$13*G44 -> 14278.973 | I44: =$B$14*H44 -> 0 | J44: =(1-$C$13)*F44*C44 -> 16575.507 | K44: =(1-$C$13)*F44*D44 -> 181819.09 | L44: =$B$15*(1-$C$13)*F44*E44 -> 26596.964 | M44: =K44+L44 -> 208416.06 | N44: =I44+J44+M44 -> 224991.56 | O44: =G44-H44-M44 -> 2633099.5 | P44: =1/(1+$C$12)^A44 -> 0.9834851 | Q44: =N44*P44 -> 221275.85
...

Sheet Executive Summary
A1: Question (e): Executive summary. Which loan should the borrower choose?
A2: Mini-Project 'The Two-Loan Comparison': $5,000 for 2 years, monthly payments. Chase Bank 10% with no fee vs. Wells Fargo Bank 7% with a 2% fee financed into the loan. Figures are linked to Sheets 1 to 3.
A4: Recommendation
A5: Take the Wells Fargo loan. Even after the $100 fee is added to the balance, its 7% rate gives a lower monthly payment, a lower total cost over the two years and a lower effective APR than Chase's 10% loan with no fee. The 3-percentage-point rate advantage saves $157.23 of interest, which is more than the $100 fee.
A7: Key figures (all formulas, linked to Sheet 1)
B8: Chase Bank | C8: Wells Fargo Bank | D8: Difference (Chase - Wells Fargo)
A9: Cash the borrower receives ($) | B9: ='1 Amortization'!B7 -> 5000 | C9: ='1 Amortization'!C7 -> 5000 | D9: =B9-C9 -> 0
A10: Origination fee, financed into the loan ($) | B10: ='1 Amortization'!B20 -> 0 | C10: ='1 Amortization'!C20 -> 100 | D10: =B10-C10 -> -100
A11: Amount owed at the start ($) | B11: ='1 Amortization'!B21 -> 5000 | C11: ='1 Amortization'!C21 -> 5100 | D11: =B11-C11 -> -100
A12: Quoted simple annual rate | B12: ='1 Amortization'!B8 -> 0.1 | C12: ='1 Amortization'!C8 -> 0.07 | D12: =B12-C12 -> 0.03
A13: Monthly payment ($) | B13: ='1 Amortization'!B27 -> 230.72463 | C13: ='1 Amortization'!C27 -> 228.34015 | D13: =B13-C13 -> 2.3844783
A14: Total of the 24 payments ($) | B14: ='1 Amortization'!B67 -> 5537.3912 | C14: ='1 Amortization'!C67 -> 5480.1637 | D14: =B14-C14 -> 57.227478
A15: Total interest paid ($) | B15: ='1 Amortization'!B68 -> 537.39116 | C15: ='1 Amortization'!C68 -> 380.16368 | D15: =B15-C15 -> 157.22748
A16: Total cost of borrowing = interest + fee ($) | B16: ='1 Amortization'!B70 -> 537.39116 | C16: ='1 Amortization'!C70 -> 480.16368 | D16: =B16-C16 -> 57.227478
A17: Nominal APR, fee-inclusive (12 x monthly IRR) | B17: ='1 Amortization'!B73 -> 0.1 | C17: ='1 Amortization'!C73 -> 0.089635729 | D17: =B17-C17 -> 0.010364271
A18: Effective annual rate, fee-inclusive ((1 + monthly IRR)^12 - 1) | B18: ='1 Amortization'!B74 -> 0.10471307 | C18: ='1 Amortization'!C74 -> 0.093411487 | D18: =B18-C18 -> 0.01130158
A20: Why Wells Fargo is the better loan
A21: 1. Monthly payment: $228.34 vs. $230.72, so $2.38 less a month. Wells Fargo amortizes a larger balance ($5,100 vs. $5,000) but at a much lower rate, and the rate effect wins.
A22: 2. Total interest and total cost: interest of $380.16 vs. $537.39. Adding the $100 fee, Wells Fargo's total cost is $480.16 vs. $537.39 for Chase, a saving of $57.23 over two years. Total cost (all payments minus cash received) is the fair basis because Wells Fargo's fee is repaid inside the payments.
A23: 3. Effective APR: the fee raises Wells Fargo's true cost from the quoted 7.00% to a nominal APR of 8.96% (9.34% effective annual with monthly compounding), still below Chase's 10.00% nominal APR (10.47% effective annual). APR is the annualised internal rate of return of the borrower's actual cash flows: $5,000 received today, 24 payments out.
A25: Two further results (linked to Sheets 2 and 3)
B26: Value
A27: Wells Fargo payoff balance minus PV of remaining payments at Chase's rate, after month 1 ($) | B27: ='2 Payoff Analysis'!H19 -> 140.18763
A28: Wells Fargo's expected NPV on 1,000 loans, funded at 2% with 6%/yr defaults and 1%/mo prepayments ($) | B28: ='3 Bank View'!B71 -> 50489.518
A29: The same NPV as a % of the $5,000,000 lent | B29: ='3 Bank View'!B72 -> 0.010097904
A30: Early payoff (Sheet 2): the borrower should not prepay or refinance the Wells Fargo loan at Chase's rate. In every month its payoff balance exceeds the value of the remaining payments discounted at 10%, so paying it off early hands the rate advantage back to the bank. For Chase the two are equal, so early payoff is a fair trade.
A31: The bank's view (Sheet 3): after expected defaults and prepayments, the 1,000-loan portfolio is worth about 1% more than the cash lent. At a 2% fee the bank breaks even near a 6% contract rate and with no fee near 8%, so the loan that is cheaper for the borrower leaves Wells Fargo only a thin margin.
